Workbook
Name 일요일: #REF!
Name 토요일: #REF!

Sheet 전체 통계
C4: 2022 | D4: 12 | E4: 1
B6: 구 분 | E6: 누적 합계 | F6: 연간 통계 | M6: 2017년 월간실적 | O6: 2018년 월간실적 | AA6: 2019년 월간실적 | AM6: 2020년 월간실적 | AY6: 2021년 월간실적 | BK6: 2022년 월간실적 | BX6: 당월 현황 | BZ6: 주차별 통계 | CF6: 당월
F7: 2017년 | G7: 2018년 | H7: 2019년 | I7: 2020년 | J7: 2021년 | K7: 2022년 | M7: 11월 | N7: 12월 | O7: 1월 | P7: 2월 | Q7: 3월 | R7: 4월 | S7: 5월 | T7: 6월 | U7: 7월 | V7: 8월 | W7: 9월 | X7: 10월 | Y7: 11월 | Z7: 12월 | AA7: 1월 | AB7: 2월 | AC7: 3월 | AD7: 4월 | AE7: 5월 | AF7: 6월 | AG7: 7월 | AH7: 8월 | AI7: 9월 | AJ7: 10월 | AK7: 11월 | AL7: 12월 | AM7: 1월 | AN7: 2월 | AO7: 3월 | AP7: 4월 | AQ7: 5월 | AR7: 6월 | AS7: 7월 | AT7: 8월 | AU7: 9월 | AV7: 10월 | AW7: 11월 | AX7: 12월 | AY7: 1월 | AZ7: 2월 | BA7: 3월 | BB7: 4월 | BC7: 5월 | BD7: 6월 | BE7: 7월 | BF7: 8월 | BG7: 9월 | BH7: 10월 | BI7: 11월 | BJ7: 12월 | BK7: 1월 | BL7: 2월 | BM7: 3월 | BN7: 4월 | BO7: 5월 | BP7: 6월 | BQ7: 7월 | BR7: 8월 | BS7: 9월 | BT7: 10월 | BU7: 11월 | BV7: 12월 | BZ7: 1주차 | CA7: 2주차 | CB7: 3주차 | CC7: 4주차 | CD7: 5주차 | CF7: 1 | CG7: 2 | CH7: 3 | CI7: 4 | CJ7: 5 | CK7: 6 | CL7: 7 | CM7: 8 | CN7: 9 | CO7: 10 | CP7: 11 | CQ7: 12 | CR7: 13 | CS7: 14 | CT7: 15 | CU7: 16 | CV7: 17 | CW7: 18 | CX7: 19 | CY7: 20 | CZ7: 21 | DA7: 22 | DB7: 23 | DC7: 24 | DD7: 25 | DE7: 26 | DF7: 27 | DG7: 28 | DH7: 29 | DI7: 30
M8: 11 | N8: 22.5 | O8: 24 | P8: 24 | Q8: 23.5 | R8: 23 | S8: 21.5 | T8: 21.5 | U8: 24 | V8: 24 | W8: 19.5 | X8: 23 | Y8: 24 | Z8: 25.5 | AA8: 24 | AB8: 19 | AC8: 23.5 | AD8: 24 | AE8: 24 | AF8: 21.5 | AG8: 25 | AH8: 23.5 | AI8: 20.5 | AJ8: 24.5 | AK8: 24.5 | AL8: 23 | AM8: 21.5 | AN8: 22.5 | AO8: 24 | AP8: 22 | AQ8: 21.5 | AR8: 23.5 | AS8: 25 | AT8: 22 | AU8: 23 | AV8: 21 | AW8: 23 | AX8: 24 | AY8: 22.5 | AZ8: 19.5 | BA8: 24 | BB8: 24 | BC8: 19.5 | BD8: 24 | BE8: 24.5 | BF8: 23 | BG8: 21 | BH8: 21 | BI8: 24 | BJ8: 24.5 | BK8: 22 | BL8: 20 | BM8: 23 | BN8: 23.5 | BO8: 23 | BS8: 21.5 | BX8: 10 | BZ8: 4.5 | CA8: 5.5 | CF8: 화 | CG8: 수 | CH8: 목 | CI8: 금 | CJ8: 토 | CK8: 일 | CL8: 월 | CM8: 화 | CN8: 수 | CO8: 목 | CP8: 금 | CQ8: 토 | CR8: 일 | CS8: 월 | CT8: 화 | CU8: 수 | CV8: 목 | CW8: 금 | CX8: 토 | CY8: 일 | CZ8: 월 | DA8: 화 | DB8: 수 | DC8: 목 | DD8: 금 | DE8: 토 | DF8: 일 | DG8: 월 | DH8: 화 | DI8: 수
B9: 1. 접수 통계 | D9: 접수 | E9: 1327 | F9: =SUM(F12,F15,F18,F21,F24,F27) -> 2153 | G9: =SUM(G12,G15,G18,G21,G24,G27) -> 35421 | H9: =SUM(H12,H15,H18,H21,H24,H27) -> 37722 | I9: =SUM(I12,I15,I18,I21,I24,I27) -> 47567 | J9: 40226 | K9: =SUM(K12,K15,K18,K21,K24,K27) -> 12974 | M9: =IF(SUM(M12,M15,M18,M21,M24,M27)=0,"",SUM(M12,M15,M18,M21,M24,M27)) -> 388 | N9: =IF(SUM(N12,N15,N18,N21,N24,N27)=0,"",SUM(N12,N15,N18,N21,N24,N27)) -> 1765 | O9: =IF(SUM(O12,O15,O18,O21,O24,O27)=0,"",SUM(O12,O15,O18,O21,O24,O27)) -> 2312 | P9: =IF(SUM(P12,P15,P18,P21,P24,P27)=0,"",SUM(P12,P15,P18,P21,P24,P27)) -> 2371 | Q9: =IF(SUM(Q12,Q15,Q18,Q21,Q24,Q27)=0,"",SUM(Q12,Q15,Q18,Q21,Q24,Q27)) -> 3048 | R9: =IF(SUM(R12,R15,R18,R21,R24,R27)=0,"",SUM(R12,R15,R18,R21,R24,R27)) -> 2876 | S9: =IF(SUM(S12,S15,S18,S21,S24,S27)=0,"",SUM(S12,S15,S18,S21,S24,S27)) -> 2748 | T9: =IF(SUM(T12,T15,T18,T21,T24,T27)=0,"",SUM(T12,T15,T18,T21,T24,T27)) -> 2957 | ... AX9: =IF(SUM(AX12,AX15,AX18,AX21,AX24,AX27)=0,"",SUM(AX12,AX15,AX18,AX21,AX24,AX27)) -> 4366 | AY9: 3761 | AZ9: 2842 | BA9: 3524 | BB9: 4292 | BC9: 3445 | BD9: 3260 | BE9: 3855 | BF9: 3355 | BG9: 3579 | BH9: 2562 | BI9: 2476 | BJ9: 3275 | BK9: 2421 | BL9: 2379 | BM9: 2498 | BN9: 2119 | BO9: 1755 | BS9: 1802 | BX9: 952 | BZ9: 437 | CA9: 515 | CF9: 97 | CG9: 92 | CH9: 100 | CI9: 114 | CJ9: 34 | CL9: 103 | CM9: 101 | CN9: 98 | CO9: 94 | CP9: 95 | CQ9: 24
D10: 평균 | E10: 73.722222 | F10: =F9/COUNT(M9:N9) -> 1076.5 | G10: =G9/COUNT(O9:Z9) -> 2951.75 | H10: =H9/COUNT(AA9:AL9) -> 3143.5 | I10: =I9/COUNT(AM9:AX9) -> 3963.9167 | J10: 3352.1667 | K10: =K9/COUNT(BK9:BV9) -> 2162.3333 | M10: =M9/M$8 -> 35.272727 | N10: =N9/N$8 -> 78.444444 | O10: =O9/O$8 -> 96.333333 | P10: =P9/P$8 -> 98.791667 | Q10: =Q9/Q$8 -> 129.70213 | R10: =R9/R$8 -> 125.04348 | S10: =S9/S$8 -> 127.81395 | T10: =T9/T$8 -> 137.53488 | ... AN10: =AN9/AN$8 -> 180.31111 | AO10: =IFERROR(AO9/AO$8,"") -> 259.75 | AP10: =IFERROR(AP9/AP$8,"") -> 233.81818 | AQ10: =IFERROR(AQ9/AQ$8,"") -> 193.30233 | AR10: =IFERROR(AR9/AR$8,"") -> 161.53191 | AS10: 150.41667 | AT10: 156.27273 | AU10: 163 | AV10: 135.61905 | AW10: =IFERROR(AW9/AW$8,"") -> 129.69565 | AX10: =IFERROR(AX9/AX$8,"") -> 181.91667 | AY10: 167.15556 | AZ10: 145.74359 | BA10: 146.83333 | BB10: 178.83333 | BC10: 176.66667 | BD10: 135.83333 | BE10: 157.34694 | BF10: 145.86957 | BG10: 170.42857 | BH10: 122 | BI10: 103.16667 | BJ10: 133.67347 | BK10: 110.04545 | BL10: 118.95 | BM10: 108.6087 | BN10: 90.170213 | BO10: 76.304348 | BS10: 83.813953 | BX10: 95.2 | BZ10: 97.111111 | CA10: 93.636364
D11: 전월 대비 | G11: =IF(COUNT(O9:Z9)<12,"",G9-F9) -> 33268 | H11: =IF(COUNT(AA9:AL9)<12,"",H9-G9) -> 2301 | I11: =IF(COUNT(AM9:AX9)<12,"",I9-H9) -> 9845 | J11: -7341 | K11: =IF(COUNT(BK9:BV9)<12,"",K9-I9) | N11: =IF(N9="","",N9-M9) -> 1377 | O11: =IF(O9="","",O9-N9) -> 547 | P11: =IF(P9="","",P9-O9) -> 59 | Q11: =IF(Q9="","",Q9-P9) -> 677 | R11: =IF(R9="","",R9-Q9) -> -172 | S11: =IF(S9="","",S9-R9) -> -128 | T11: =IF(T9="","",T9-S9) -> 209 | U11: =IF(U9="","",U9-T9) -> 426 | ... AL11: =IF(AL9="","",AL9-AK9) -> -32 | AM11: =IF(AM9="","",AM9-Z9) -> 170 | AN11: =IF(AN9="","",AN9-AM9) -> 932 | AO11: =IF(AO9="","",AO9-AN9) -> 2177 | AP11: =IF(AP9="","",AP9-AO9) -> -1090 | AQ11: =IF(AQ9="","",AQ9-AP9) -> -988 | AR11: =IF(AR9="","",AR9-AQ9) -> -360 | AS11: =IF(AS9="","",AS9-AR9) -> -186 | AT11: =IF(AT9="","",AT9-AS9) -> -172 | AU11: =IF(AU9="","",AU9-AT9) -> 311 | ... AX11: =IF(AX9="","",AX9-AW9) -> 1383 | AY11: -605 | AZ11: -919 | BA11: 682 | BB11: 768 | BC11: -847 | BD11: -185 | BE11: 595 | BF11: -500 | BG11: 224 | BH11: -1017 | BJ11: 799
C12: 가. CSONE서울1센터 | D12: 접수 | E12: 272 | F12: =SUM(M12:N12) -> 415 | G12: =SUM(O12:Z12) -> 8298 | H12: =SUM(AA12:AL12) -> 8188 | I12: =SUM(AM12:AX12) -> 10040 | J12: 9671 | K12: =SUM(BK12:BV12) -> 2693 | M12: 76 | N12: 339 | O12: 534 | P12: 486 | Q12: 779 | R12: 668 | S12: 685 | T12: 675 | U12: 874 | V12: 958 | W12: 624 | X12: 704 | Y12: 624 | Z12: 687 | AA12: 784 | AB12: 603 | AC12: 666 | AD12: 841 | AE12: 642 | AF12: 561 | AG12: 720 | AH12: 793 | AI12: 641 | AJ12: 627 | AK12: 644 | AL12: 666 | AM12: 714 | AN12: 869 | AO12: 1355 | AP12: 1166 | AQ12: 853 | AR12: 761 | AS12: 715 | AT12: 749 | AU12: 756 | AV12: 562 | AW12: 608 | AX12: 932 | AY12: 834 | AZ12: 638 | BA12: 921 | BB12: 1078 | BC12: 901 | BD12: 783 | BE12: 925 | BF12: 817 | BG12: 866 | BH12: 658 | BI12: 539 | BJ12: 711 | BK12: 490 | BL12: 466 | BM12: 582 | BN12: 451 | BO12: 369 | BS12: 335 | BX12: 209 | BZ12: 99 | CA12: 110 | CF12: 25 | CG12: 20 | CH12: 27 | CI12: 21 | CJ12: 6 | CL12: 25 | CM12: 17 | CN12: 19 | CO12: 21 | CP12: 21 | CQ12: 7
D13: 평균 | E13: 15.111111 | F13: =F12/COUNT(M12:N12) -> 207.5 | G13: =G12/COUNT(O12:Z12) -> 691.5 | H13: =H12/COUNT(AA12:AL12) -> 682.33333 | I13: =I12/COUNT(AM12:AX12) -> 836.66667 | J13: 805.91667 | K13: =K12/COUNT(BK12:BV12) -> 448.83333 | M13: =M12/M$8 -> 6.9090909 | N13: =N12/N$8 -> 15.066667 | O13: =O12/O$8 -> 22.25 | P13: =P12/P$8 -> 20.25 | Q13: =Q12/Q$8 -> 33.148936 | R13: =R12/R$8 -> 29.043478 | S13: =S12/S$8 -> 31.860465 | T13: =T12/T$8 -> 31.395349 | ... AN13: =AN12/AN$8 -> 38.622222 | AO13: =IFERROR(AO12/AO$8,"") -> 56.458333 | AP13: =IFERROR(AP12/AP$8,"") -> 53 | AQ13: =IFERROR(AQ12/AQ$8,"") -> 39.674419 | AR13: =IFERROR(AR12/AR$8,"") -> 32.382979 | AS13: 29.791667 | AT13: 34.045455 | AU13: 32.869565 | AV13: 26.761905 | AW13: =IFERROR(AW12/AW$8,"") -> 26.434783 | AX13: =IFERROR(AX12/AX$8,"") -> 38.833333 | AY13: 37.066667 | AZ13: 32.717949 | BA13: 38.375 | BB13: 44.916667 | BC13: 46.205128 | BD13: 32.625 | BE13: 37.755102 | BF13: 35.521739 | BG13: 41.238095 | BH13: 31.333333 | BI13: 22.458333 | BJ13: 29.020408 | BK13: 22.272727 | BL13: 23.3 | BM13: 25.304348 | BN13: 19.191489 | BO13: 16.043478 | BS13: 15.581395 | BX13: 20.9 | BZ13: 22 | CA13: 20
D14: 전월 대비 | G14: =G12-F12 -> 7883 | H14: =H12-G12 -> -110 | I14: =I12-H12 -> 1852 | J14: -369 | K14: =K12-I12 -> -7347 | N14: =IF(N12="","",N12-M12) -> 263 | O14: =IF(O12="","",O12-N12) -> 195 | P14: =IF(P12="","",P12-O12) -> -48 | Q14: =IF(Q12="","",Q12-P12) -> 293 | R14: =IF(R12="","",R12-Q12) -> -111 | S14: =IF(S12="","",S12-R12) -> 17 | T14: =IF(T12="","",T12-S12) -> -10 | U14: =IF(U12="","",U12-T12) -> 199 | ... AL14: =IF(AL12="","",AL12-AK12) -> 22 | AM14: =IF(AM12="","",AM12-Z12) -> 27 | AN14: =IF(AN12="","",AN12-AM12) -> 155 | AO14: =IF(AO12="","",AO12-AN12) -> 486 | AP14: =IF(AP12="","",AP12-AO12) -> -189 | AQ14: =IF(AQ12="","",AQ12-AP12) -> -313 | AR14: =IF(AR12="","",AR12-AQ12) -> -92 | AS14: =IF(AS12="","",AS12-AR12) -> -46 | AT14: =IF(AT12="","",AT12-AS12) -> 34 | AU14: =IF(AU12="","",AU12-AT12) -> 7 | ... AX14: =IF(AX12="","",AX12-AW12) -> 324 | AY14: -98 | AZ14: -196 | BA14: 283 | BB14: 157 | BC14: -177 | BD14: -118 | BE14: 142 | BF14: -108 | BG14: 49 | BH14: -208 | BJ14: 172
C15: 나. LB휴넷서울센터 | D15: 접수 | E15: 269 | F15: =SUM(M15:N15) -> 270 | G15: =SUM(O15:Z15) -> 6828 | H15: =SUM(AA15:AL15) -> 7105 | I15: =SUM(AM15:AX15) -> 8984 | J15: 6040 | K15: =SUM(BK15:BV15) -> 2479 | M15: 40 | N15: 230 | O15: 374 | P15: 506 | Q15: 555 | R15: 546 | S15: 494 | T15: 581 | U15: 595 | V15: 663 | W15: 529 | X15: 734 | Y15: 662 | Z15: 589 | AA15: 635 | AB15: 548 | AC15: 568 | AD15: 639 | AE15: 604 | AF15: 525 | AG15: 686 | AH15: 710 | AI15: 594 | AJ15: 561 | AK15: 483 | AL15: 552 | AM15: 536 | AN15: 770 | AO15: 1126 | AP15: 962 | AQ15: 835 | AR15: 746 | AS15: 699 | AT15: 655 | AU15: 766 | AV15: 566 | AW15: 550 | AX15: 773 | AY15: 652 | AZ15: 418 | BA15: 484 | BB15: 566 | BC15: 422 | BD15: 398 | BE15: 514 | BF15: 542 | BG15: 589 | BH15: 380 | BI15: 458 | BJ15: 617 | BK15: 466 | BL15: 465 | BM15: 481 | BN15: 388 | BO15: 341 | BS15: 338 | BX15: 180 | BZ15: 91 | CA15: 89 | CF15: 18 | CG15: 23 | CH15: 17 | CI15: 26 | CJ15: 7 | CL15: 17 | CM15: 17 | CN15: 19 | CO15: 18 | CP15: 14 | CQ15: 4
D16: 평균 | E16: 14.944444 | F16: =F15/COUNT(M15:N15) -> 135 | G16: =G15/COUNT(O15:Z15) -> 569 | H16: =H15/COUNT(AA15:AL15) -> 592.08333 | I16: =I15/COUNT(AM15:AX15) -> 748.66667 | J16: 503.33333 | K16: =K15/COUNT(BK15:BV15) -> 413.16667 | M16: =M15/M$8 -> 3.6363636 | N16: =N15/N$8 -> 10.222222 | O16: =O15/O$8 -> 15.583333 | P16: =P15/P$8 -> 21.083333 | Q16: =Q15/Q$8 -> 23.617021 | R16: =R15/R$8 -> 23.73913 | S16: =S15/S$8 -> 22.976744 | T16: =T15/T$8 -> 27.023256 | ... AN16: =AN15/AN$8 -> 34.222222 | AO16: =IFERROR(AO15/AO$8,"") -> 46.916667 | AP16: =IFERROR(AP15/AP$8,"") -> 43.727273 | AQ16: =IFERROR(AQ15/AQ$8,"") -> 38.837209 | AR16: =IFERROR(AR15/AR$8,"") -> 31.744681 | AS16: 29.125 | AT16: 29.772727 | AU16: 33.304348 | AV16: 26.952381 | AW16: =IFERROR(AW15/AW$8,"") -> 23.913043 | AX16: =IFERROR(AX15/AX$8,"") -> 32.208333 | AY16: 28.977778 | AZ16: 21.435897 | BA16: 20.166667 | BB16: 23.583333 | BC16: 21.641026 | BD16: 16.583333 | BE16: 20.979592 | BF16: 23.565217 | BG16: 28.047619 | BH16: 18.095238 | BI16: 19.083333 | BJ16: 25.183673 | BK16: 21.181818 | BL16: 23.25 | BM16: 20.913043 | BN16: 16.510638 | BO16: 14.826087 | BS16: 15.72093 | BX16: 18 | BZ16: 20.222222 | CA16: 16.181818
D17: 전월 대비 | G17: =G15-F15 -> 6558 | H17: =H15-G15 -> 277 | I17: =I15-H15 -> 1879 | J17: -2944 | K17: =K15-I15 -> -6505 | N17: =IF(N15="","",N15-M15) -> 190 | O17: =IF(O15="","",O15-N15) -> 144 | P17: =IF(P15="","",P15-O15) -> 132 | Q17: =IF(Q15="","",Q15-P15) -> 49 | R17: =IF(R15="","",R15-Q15) -> -9 | S17: =IF(S15="","",S15-R15) -> -52 | T17: =IF(T15="","",T15-S15) -> 87 | U17: =IF(U15="","",U15-T15) -> 14 | ... AL17: =IF(AL15="","",AL15-AK15) -> 69 | AM17: =IF(AM15="","",AM15-Z15) -> -53 | AN17: =IF(AN15="","",AN15-AM15) -> 234 | AO17: =IF(AO15="","",AO15-AN15) -> 356 | AP17: =IF(AP15="","",AP15-AO15) -> -164 | AQ17: =IF(AQ15="","",AQ15-AP15) -> -127 | AR17: =IF(AR15="","",AR15-AQ15) -> -89 | AS17: =IF(AS15="","",AS15-AR15) -> -47 | AT17: =IF(AT15="","",AT15-AS15) -> -44 | AU17: =IF(AU15="","",AU15-AT15) -> 111 | ... AX17: =IF(AX15="","",AX15-AW15) -> 223 | AY17: -121 | AZ17: -234 | BA17: 66 | BB17: 82 | BC17: -144 | BD17: -24 | BE17: 116 | BF17: 28 | BG17: 47 | BH17: -209 | BJ17: 159
C18: 다. CSONE부산1센터 | D18: 접수 | E18: 240 | F18: =SUM(M18:N18) -> 462 | G18: =SUM(O18:Z18) -> 6620 | H18: =SUM(AA18:AL18) -> 6552 | I18: =SUM(AM18:AX18) -> 8742 | J18: 6987 | K18: =SUM(BK18:BV18) -> 2219 | M18: 87 | N18: 375 | O18: 484 | P18: 479 | Q18: 507 | R18: 557 | S18: 571 | T18: 478 | U18: 617 | V18: 639 | W18: 534 | X18: 630 | Y18: 579 | Z18: 545 | AA18: 560 | AB18: 509 | AC18: 534 | AD18: 648 | AE18: 532 | AF18: 520 | AG18: 588 | AH18: 540 | AI18: 527 | AJ18: 600 | AK18: 535 | AL18: 459 | AM18: 543 | AN18: 712 | AO18: 1163 | AP18: 911 | AQ18: 815 | AR18: 719 | AS18: 686 | AT18: 593 | AU18: 629 | AV18: 566 | AW18: 565 | AX18: 840 | AY18: 649 | AZ18: 521 | BA18: 576 | BB18: 729 | BC18: 610 | BD18: 610 | BE18: 676 | BF18: 577 | BG18: 595 | BH18: 427 | BI18: 439 | BJ18: 578 | BK18: 413 | BL18: 408 | BM18: 389 | BN18: 356 | BO18: 319 | BS18: 334 | BX18: 160 | BZ18: 71 | CA18: 89 | CF18: 14 | CG18: 11 | CH18: 21 | CI18: 19 | CJ18: 6 | CL18: 15 | CM18: 19 | CN18: 17 | CO18: 16 | CP18: 20 | CQ18: 2
D19: 평균 | E19: 13.333333 | F19: =F18/COUNT(M18:N18) -> 231 | G19: =G18/COUNT(O18:Z18) -> 551.66667 | H19: =H18/COUNT(AA18:AL18) -> 546 | I19: =I18/COUNT(AM18:AX18) -> 728.5 | J19: 582.25 | K19: =K18/COUNT(BK18:BV18) -> 369.83333 | M19: =M18/M$8 -> 7.9090909 | N19: =N18/N$8 -> 16.666667 | O19: =O18/O$8 -> 20.166667 | P19: =P18/P$8 -> 19.958333 | Q19: =Q18/Q$8 -> 21.574468 | R19: =R18/R$8 -> 24.217391 | S19: =S18/S$8 -> 26.55814 | T19: =T18/T$8 -> 22.232558 | ... AN19: =AN18/AN$8 -> 31.644444 | AO19: =IFERROR(AO18/AO$8,"") -> 48.458333 | AP19: =IFERROR(AP18/AP$8,"") -> 41.409091 | AQ19: =IFERROR(AQ18/AQ$8,"") -> 37.906977 | AR19: =IFERROR(AR18/AR$8,"") -> 30.595745 | AS19: 28.583333 | AT19: 26.954545 | AU19: 27.347826 | AV19: 26.952381 | AW19: =IFERROR(AW18/AW$8,"") -> 24.565217 | AX19: =IFERROR(AX18/AX$8,"") -> 35 | AY19: 28.844444 | AZ19: 26.717949 | BA19: 24 | BB19: 30.375 | BC19: 31.282051 | BD19: 25.416667 | BE19: 27.591837 | BF19: 25.086957 | BG19: 28.333333 | BH19: 20.333333 | BI19: 18.291667 | BJ19: 23.591837 | BK19: 18.772727 | BL19: 20.4 | BM19: 16.913043 | BN19: 15.148936 | BO19: 13.869565 | BS19: 15.534884 | BX19: 16 | BZ19: 15.777778 | CA19: 16.181818
D20: 전월 대비 | G20: =G18-F18 -> 6158 | H20: =H18-G18 -> -68 | I20: =I18-H18 -> 2190 | J20: -1755 | K20: =K18-I18 -> -6523 | N20: =IF(N18="","",N18-M18) -> 288 | O20: =IF(O18="","",O18-N18) -> 109 | P20: =IF(P18="","",P18-O18) -> -5 | Q20: =IF(Q18="","",Q18-P18) -> 28 | R20: =IF(R18="","",R18-Q18) -> 50 | S20: =IF(S18="","",S18-R18) -> 14 | T20: =IF(T18="","",T18-S18) -> -93 | U20: =IF(U18="","",U18-T18) -> 139 | ... AL20: =IF(AL18="","",AL18-AK18) -> -76 | AM20: =IF(AM18="","",AM18-Z18) -> -2 | AN20: =IF(AN18="","",AN18-AM18) -> 169 | AO20: =IF(AO18="","",AO18-AN18) -> 451 | AP20: =IF(AP18="","",AP18-AO18) -> -252 | AQ20: =IF(AQ18="","",AQ18-AP18) -> -96 | AR20: =IF(AR18="","",AR18-AQ18) -> -96 | AS20: =IF(AS18="","",AS18-AR18) -> -33 | AT20: =IF(AT18="","",AT18-AS18) -> -93 | AU20: =IF(AU18="","",AU18-AT18) -> 36 | ... AX20: =IF(AX18="","",AX18-AW18) -> 275 | AY20: -191 | AZ20: -128 | BA20: 55 | BB20: 153 | BC20: -119 | BD20: 0 | BE20: 66 | BF20: -99 | BG20: 18 | BH20: -168 | BJ20: 139
C21: 라. CSONE부산2센터 | D21: 접수 | E21: 234 | F21: =SUM(M21:N21) -> 338 | G21: =SUM(O21:Z21) -> 6808 | H21: =SUM(AA21:AL21) -> 8098 | I21: =SUM(AM21:AX21) -> 10315 | J21: 8624 | K21: =SUM(BK21:BV21) -> 2710 | M21: 74 | N21: 264 | O21: 349 | P21: 445 | Q21: 647 | R21: 519 | S21: 459 | T21: 562 | U21: 676 | V21: 682 | W21: 549 | X21: 658 | Y21: 640 | Z21: 622 | AA21: 650 | AB21: 570 | AC21: 691 | AD21: 783 | AE21: 609 | AF21: 570 | AG21: 821 | AH21: 761 | AI21: 641 | AJ21: 744 | AK21: 648 | AL21: 610 | AM21: 694 | AN21: 874 | AO21: 1278 | AP21: 1163 | AQ21: 878 | AR21: 775 | AS21: 792 | AT21: 759 | AU21: 900 | AV21: 666 | AW21: 640 | AX21: 896 | AY21: 797 | AZ21: 638 | BA21: 729 | BB21: 947 | BC21: 803 | BD21: 733 | BE21: 883 | BF21: 698 | BG21: 761 | BH21: 515 | BI21: 495 | BJ21: 625 | BK21: 541 | BL21: 519 | BM21: 540 | BN21: 468 | BO21: 325 | BS21: 317 | BX21: 148 | BZ21: 64 | CA21: 84 | CF21: 13 | CG21: 11 | CH21: 14 | CI21: 22 | CJ21: 4 | CL21: 19 | CM21: 17 | CN21: 15 | CO21: 16 | CP21: 13 | CQ21: 4
D22: 평균 | E22: 13 | F22: =F21/COUNT(M21:N21) -> 169 | G22: =G21/COUNT(O21:Z21) -> 567.33333 | H22: =H21/COUNT(AA21:AL21) -> 674.83333 | I22: =I21/COUNT(AM21:AX21) -> 859.58333 | J22: 718.66667 | K22: =K21/COUNT(BK21:BV21) -> 451.66667 | M22: =M21/M$8 -> 6.7272727 | N22: =N21/N$8 -> 11.733333 | O22: =O21/O$8 -> 14.541667 | P22: =P21/P$8 -> 18.541667 | Q22: =Q21/Q$8 -> 27.531915 | R22: =R21/R$8 -> 22.565217 | S22: =S21/S$8 -> 21.348837 | T22: =T21/T$8 -> 26.139535 | ... AN22: =AN21/AN$8 -> 38.844444 | AO22: =IFERROR(AO21/AO$8,"") -> 53.25 | AP22: =IFERROR(AP21/AP$8,"") -> 52.863636 | AQ22: =IFERROR(AQ21/AQ$8,"") -> 40.837209 | AR22: =IFERROR(AR21/AR$8,"") -> 32.978723 | AS22: 33 | AT22: 34.5 | AU22: 39.130435 | AV22: 31.714286 | AW22: =IFERROR(AW21/AW$8,"") -> 27.826087 | AX22: =IFERROR(AX21/AX$8,"") -> 37.333333 | AY22: 35.422222 | AZ22: 32.717949 | BA22: 30.375 | BB22: 39.458333 | BC22: 41.179487 | BD22: 30.541667 | BE22: 36.040816 | BF22: 30.347826 | BG22: 36.238095 | BH22: 24.52381 | BI22: 20.625 | BJ22: 25.510204 | BK22: 24.590909 | BL22: 25.95 | BM22: 23.478261 | BN22: 19.914894 | BO22: 14.130435 | BS22: 14.744186 | BX22: 14.8 | BZ22: 14.222222 | CA22: 15.272727
D23: 전월 대비 | G23: =G21-F21 -> 6470 | H23: =H21-G21 -> 1290 | I23: =I21-H21 -> 2217 | J23: -1691 | K23: =K21-I21 -> -7605 | N23: =IF(N21="","",N21-M21) -> 190 | O23: =IF(O21="","",O21-N21) -> 85 | P23: =IF(P21="","",P21-O21) -> 96 | Q23: =IF(Q21="","",Q21-P21) -> 202 | R23: =IF(R21="","",R21-Q21) -> -128 | S23: =IF(S21="","",S21-R21) -> -60 | T23: =IF(T21="","",T21-S21) -> 103 | U23: =IF(U21="","",U21-T21) -> 114 | ... AL23: =IF(AL21="","",AL21-AK21) -> -38 | AM23: =IF(AM21="","",AM21-Z21) -> 72 | AN23: =IF(AN21="","",AN21-AM21) -> 180 | AO23: =IF(AO21="","",AO21-AN21) -> 404 | AP23: =IF(AP21="","",AP21-AO21) -> -115 | AQ23: =IF(AQ21="","",AQ21-AP21) -> -285 | AR23: =IF(AR21="","",AR21-AQ21) -> -103 | AS23: =IF(AS21="","",AS21-AR21) -> 17 | AT23: =IF(AT21="","",AT21-AS21) -> -33 | AU23: =IF(AU21="","",AU21-AT21) -> 141 | ... AX23: =IF(AX21="","",AX21-AW21) -> 256 | AY23: -99 | AZ23: -159 | BA23: 91 | BB23: 218 | BC23: -144 | BD23: -70 | BE23: 150 | BF23: -185 | BG23: 63 | BH23: -246 | BJ23: 130
C24: 마.LB휴넷전주센터 | D24: 접수 | E24: 312 | F24: =SUM(M24:N24) -> 436 | G24: =SUM(O24:Z24) -> 6321 | H24: =SUM(AA24:AL24) -> 7592 | I24: =SUM(AM24:AX24) -> 9479 | J24: 8903 | K24: =SUM(BK24:BV24) -> 2802 | M24: 55 | N24: 381 | O24: 453 | P24: 332 | Q24: 461 | R24: 557 | S24: 500 | T24: 634 | U24: 582 | V24: 645 | W24: 484 | X24: 590 | Y24: 571 | Z24: 512 | AA24: 639 | AB24: 552 | AC24: 603 | AD24: 657 | AE24: 593 | AF24: 504 | AG24: 730 | AH24: 698 | AI24: 661 | AJ24: 691 | AK24: 626 | AL24: 638 | AM24: 638 | AN24: 832 | AO24: 1311 | AP24: 942 | AQ24: 775 | AR24: 790 | AS24: 718 | AT24: 682 | AU24: 698 | AV24: 549 | AW24: 620 | AX24: 924 | AY24: 829 | AZ24: 626 | BA24: 814 | BB24: 972 | BC24: 709 | BD24: 736 | BE24: 857 | BF24: 721 | BG24: 768 | BH24: 582 | BI24: 545 | BJ24: 744 | BK24: 508 | BL24: 520 | BM24: 505 | BN24: 446 | BO24: 354 | BS24: 469 | BX24: 228 | BZ24: 99 | CA24: 129 | CF24: 23 | CG24: 23 | CH24: 19 | CI24: 24 | CJ24: 10 | CL24: 26 | CM24: 29 | CN24: 23 | CO24: 21 | CP24: 24 | CQ24: 6
D25: 평균 | E25: 17.333333 | F25: =F24/COUNT(M24:N24) -> 218 | G25: =G24/COUNT(O24:Z24) -> 526.75 | H25: =H24/COUNT(AA24:AL24) -> 632.66667 | I25: =I24/COUNT(AM24:AX24) -> 789.91667 | J25: 741.91667 | K25: =K24/COUNT(BK24:BV24) -> 467 | M25: =M24/M$8 -> 5 | N25: =N24/N$8 -> 16.933333 | O25: =O24/O$8 -> 18.875 | P25: =P24/P$8 -> 13.833333 | Q25: =Q24/Q$8 -> 19.617021 | R25: =R24/R$8 -> 24.217391 | S25: =S24/S$8 -> 23.255814 | T25: =T24/T$8 -> 29.488372 | ... AN25: =AN24/AN$8 -> 36.977778 | AO25: =IFERROR(AO24/AO$8,"") -> 54.625 | AP25: =IFERROR(AP24/AP$8,"") -> 42.818182 | AQ25: =IFERROR(AQ24/AQ$8,"") -> 36.046512 | AR25: =IFERROR(AR24/AR$8,"") -> 33.617021 | AS25: 29.916667 | AT25: 31 | AU25: 30.347826 | AV25: 26.142857 | AW25: =IFERROR(AW24/AW$8,"") -> 26.956522 | AX25: =IFERROR(AX24/AX$8,"") -> 38.5 | AY25: 36.844444 | AZ25: 32.102564 | BA25: 33.916667 | BB25: 40.5 | BC25: 36.358974 | BD25: 30.666667 | BE25: 34.979592 | BF25: 31.347826 | BG25: 36.571429 | BH25: 27.714286 | BI25: 22.708333 | BJ25: 30.367347 | BK25: 23.090909 | BL25: 26 | BM25: 21.956522 | BN25: 18.978723 | BO25: 15.391304 | BS25: 21.813953 | BX25: 22.8 | BZ25: 22 | CA25: 23.454545
D26: 전월 대비 | G26: =G24-F24 -> 5885 | H26: =H24-G24 -> 1271 | I26: =I24-H24 -> 1887 | J26: -576 | K26: =K24-I24 -> -6677 | N26: =IF(N24="","",N24-M24) -> 326 | O26: =IF(O24="","",O24-N24) -> 72 | P26: =IF(P24="","",P24-O24) -> -121 | Q26: =IF(Q24="","",Q24-P24) -> 129 | R26: =IF(R24="","",R24-Q24) -> 96 | S26: =IF(S24="","",S24-R24) -> -57 | T26: =IF(T24="","",T24-S24) -> 134 | U26: =IF(U24="","",U24-T24) -> -52 | ... AL26: =IF(AL24="","",AL24-AK24) -> 12 | AM26: =IF(AM24="","",AM24-Z24) -> 126 | AN26: =IF(AN24="","",AN24-AM24) -> 194 | AO26: =IF(AO24="","",AO24-AN24) -> 479 | AP26: =IF(AP24="","",AP24-AO24) -> -369 | AQ26: =IF(AQ24="","",AQ24-AP24) -> -167 | AR26: =IF(AR24="","",AR24-AQ24) -> 15 | AS26: =IF(AS24="","",AS24-AR24) -> -72 | AT26: =IF(AT24="","",AT24-AS24) -> -36 | AU26: =IF(AU24="","",AU24-AT24) -> 16 | ... AX26: =IF(AX24="","",AX24-AW24) -> 304 | AY26: -95 | AZ26: -203 | BA26: 188 | BB26: 158 | BC26: -263 | BD26: 27 | BE26: 121 | BF26: -136 | BG26: 47 | BH26: -186 | BJ26: 199
C27: 바.기타 | D27: 접수 | E27: 0 | F27: =SUM(M27:N27) -> 232 | G27: =SUM(O27:Z27) -> 546 | H27: =SUM(AA27:AL27) -> 187 | I27: =SUM(AM27:AX27) -> 7 | J27: 1 | K27: =SUM(BK27:BV27) -> 71 | M27: 56 | N27: 176 | O27: 118 | P27: 123 | Q27: 99 | R27: 29 | S27: 39 | T27: 27 | U27: 39 | V27: 31 | W27: 19 | X27: 14 | Y27: 8 | Z27: 0 | AA27: 4 | AB27: 42 | AC27: 35 | AD27: 34 | AE27: 4 | AF27: 6 | AG27: 7 | AH27: 9 | AI27: 6 | AJ27: 11 | AK27: 25 | AL27: 4 | AM27: 0 | AN27: 0 | AO27: 1 | AP27: 0 | AQ27: 0 | AR27: 5 | AS27: 0 | AT27: 0 | AU27: 0 | AV27: 0 | AW27: 0 | AX27: 1 | AY27: 0 | AZ27: 1 | BA27: 0 | BB27: 0 | BD27: 0 | BE27: 0 | BF27: 0 | BG27: 0 | BH27: 0 | BI27: 0 | BJ27: 0 | BK27: 3 | BL27: 1 | BM27: 1 | BN27: 10 | BO27: 47 | BS27: 9 | BX27: 27 | BZ27: 13 | CA27: 14 | CF27: 4 | CG27: 4 | CH27: 2 | CI27: 2 | CJ27: 1 | CL27: 1 | CM27: 2 | CN27: 5 | CO27: 2 | CP27: 3 | CQ27: 1
D28: 평균 | E28: 0 | F28: =F27/COUNT(M27:N27) -> 116 | G28: =G27/COUNT(O27:Z27) -> 45.5 | H28: =H27/COUNT(AA27:AL27) -> 15.583333 | I28: =I27/COUNT(AM27:AX27) -> 0.58333333 | J28: 0.090909091 | K28: =K27/COUNT(BK27:BV27) -> 11.833333 | M28: =M27/M$8 -> 5.0909091 | N28: =N27/N$8 -> 7.8222222 | O28: =O27/O$8 -> 4.9166667 | P28: =P27/P$8 -> 5.125 | Q28: =Q27/Q$8 -> 4.212766 | R28: =R27/R$8 -> 1.2608696 | S28: =S27/S$8 -> 1.8139535 | T28: =T27/T$8 -> 1.255814 | ... AP28: =AP27/AP$8 -> 0 | AQ28: =IFERROR(AQ27/AQ$8,"") -> 0 | AR28: =IFERROR(AR27/AR$8,"") -> 0.21276596 | AS28: 0 | AT28: 0 | AU28: 0 | AV28: 0 | AW28: =IFERROR(AW27/AW$8,"") -> 0 | AX28: =IFERROR(AX27/AX$8,"") -> 0.041666667 | AY28: 0 | AZ28: 0.051282051 | BA28: 0 | BB28: 0 | BC28: 0 | BD28: 0 | BE28: 0 | BF28: 0 | BG28: 0 | BH28: 0 | BI28: 0 | BJ28: 0 | BK28: 0.13636364 | BL28: 0.05 | BM28: 0.043478261 | BN28: 0.42553191 | BO28: 2.0434783 | BS28: 0.41860465 | BX28: 2.7 | BZ28: 2.8888889 | CA28: 2.5454545
D29: 전월 대비 | G29: =G27-F27 -> 314 | H29: =H27-G27 -> -359 | I29: =I27-H27 -> -180 | J29: -6 | K29: =K27-I27 -> 64 | N29: =IF(N27="","",N27-M27) -> 120 | O29: =IF(O27="","",O27-N27) -> -58 | P29: =IF(P27="","",P27-O27) -> 5 | Q29: =IF(Q27="","",Q27-P27) -> -24 | R29: =IF(R27="","",R27-Q27) -> -70 | S29: =IF(S27="","",S27-R27) -> 10 | T29: =IF(T27="","",T27-S27) -> -12 | U29: =IF(U27="","",U27-T27) -> 12 | ... AL29: =IF(AL27="","",AL27-AK27) -> -21 | AM29: =IF(AM27="","",AM27-Z27) -> 0 | AN29: =IF(AN27="","",AN27-AM27) -> 0 | AO29: =IF(AO27="","",AO27-AN27) -> 1 | AP29: =IF(AP27="","",AP27-AO27) -> -1 | AQ29: =IF(AQ27="","",AQ27-AP27) -> 0 | AR29: =IF(AR27="","",AR27-AQ27) -> 5 | AS29: =IF(AS27="","",AS27-AR27) -> -5 | AT29: =IF(AT27="","",AT27-AS27) -> 0 | AU29: =IF(AU27="","",AU27-AT27) -> 0 | ... AX29: =IF(AX27="","",AX27-AW27) -> 1 | AY29: -1 | AZ29: 1 | BA29: -1 | BB29: 0 | BD29: 0 | BE29: 0 | BF29: 0 | BG29: 0 | BH29: 0 | BJ29: 0
B30: 2. 방문 AS 접수
C31: 가. 방문AS 접수건 | E31: 235 | F31: =SUM(M31:N31) -> 35 | G31: =SUM(O31:Z31) -> 4294 | H31: =SUM(AA31:AL31) -> 3191 | I31: =SUM(AM31:AX31) -> 4174 | J31: 4210 | K31: =SUM(BK31:BV31) -> 2055 | M31: 6 | N31: 29 | O31: 52 | P31: 30 | Q31: 267 | R31: 251 | S31: 426 | T31: 555 | U31: 379 | V31: 456 | W31: 464 | X31: 518 | Y31: 417 | Z31: 479 | AA31: 557 | AB31: 570 | AC31: 343 | AD31: 241 | AE31: 128 | AF31: 151 | AG31: 316 | AH31: 335 | AI31: 140 | AJ31: 73 | AK31: 154 | AL31: 183 | AM31: 265 | AN31: 387 | AO31: 463 | AP31: 492 | AQ31: 336 | AR31: 354 | AS31: 414 | AT31: 380 | AU31: 329 | AV31: 207 | AW31: 217 | AX31: 330 | AY31: 0 | AZ31: 202 | BA31: 285 | BB31: 503 | BC31: 366 | BD31: 369 | BE31: 582 | BF31: 411 | BG31: 446 | BH31: 325 | BI31: 318 | BJ31: 403 | BK31: 305 | BL31: 318 | BM31: 438 | BN31: 373 | BO31: 280 | BS31: 341 | BX31: 119 | BZ31: 51 | CA31: 68 | CF31: 15 | CG31: 11 | CH31: 9 | CI31: 11 | CJ31: 5 | CL31: 12 | CM31: 18 | CN31: 14 | CO31: 7 | CP31: 15 | CQ31: 2
C32: 다 AS접수 비율 | E32: 0.17709118 | F32: =F31/F9 -> 0.016256386 | G32: =G31/G9 -> 0.12122752 | H32: =H31/H9 -> 0.084592545 | I32: =I31/I9 -> 0.087749911 | J32: 0.10465868 | K32: =K31/K9 -> 0.15839371 | M32: =IF(IFERROR(M31/M9,"")=0,"",IFERROR(M31/M9,"")) -> 0.015463918 | N32: =IF(IFERROR(N31/N9,"")=0,"",IFERROR(N31/N9,"")) -> 0.016430595 | O32: =IF(IFERROR(O31/O9,"")=0,"",IFERROR(O31/O9,"")) -> 0.022491349 | P32: =IF(IFERROR(P31/P9,"")=0,"",IFERROR(P31/P9,"")) -> 0.012652889 | Q32: =IF(IFERROR(Q31/Q9,"")=0,"",IFERROR(Q31/Q9,"")) -> 0.087598425 | R32: =IF(IFERROR(R31/R9,"")=0,"",IFERROR(R31/R9,"")) -> 0.087273992 | S32: =IF(IFERROR(S31/S9,"")=0,"",IFERROR(S31/S9,"")) -> 0.15502183 | T32: =IF(IFERROR(T31/T9,"")=0,"",IFERROR(T31/T9,"")) -> 0.18769023 | ... AS32: =IF(IFERROR(AS31/AS9,"")=0,"",IFERROR(AS31/AS9,"")) -> 0.11468144 | AT32: 0.11052938 | AU32: 0.087756735 | AV32: =AV31/AV9 -> 0.071158474 | AW32: =IF(IFERROR(AW31/AW9,"")=0,"",IFERROR(AW31/AW9,"")) -> 0.072745558 | AX32: =IF(IFERROR(AX31/AX9,"")=0,"",IFERROR(AX31/AX9,"")) -> 0.075584059 | AZ32: 0.071076707 | BA32: 0.080874007 | BB32: 0.11719478 | BC32: 0.10624093 | BD32: 0.11319018 | BE32: 0.15097276 | BF32: 0.12250373 | BG32: 0.12461581 | BH32: 0.12685402 | BI32: 0.12843296 | BJ32: 0.12305344 | BK32: 0.125981 | BL32: 0.13366961 | BM32: 0.17534027 | BN32: 0.17602643 | BO32: 0.15954416 | BS32: 0.18923418 | BX32: 0.125 | BZ32: 0.11670481 | CA32: 0.13203883 | CF32: 0.15463918 | CG32: 0.11956522 | CH32: 0.09 | CI32: 0.096491228 | CJ32: 0.14705882 | CL32: 0.11650485 | CM32: 0.17821782 | CN32: 0.14285714 | CO32: 0.074468085 | CP32: 0.15789474 | CQ32: 0.083333333
C33: 나 평균 접수건 | E33: 13.055556 | F33: =IFERROR(F31/COUNT(M31:N31),"") -> 17.5 | G33: =IFERROR(G31/COUNT(O31:Z31),"") -> 357.83333 | H33: =IFERROR(H31/COUNT(AA31:AL31),"") -> 265.91667 | I33: =IFERROR(I31/COUNT(AM31:AX31),"") -> 347.83333 | J33: 350.83333 | K33: =IFERROR(K31/COUNT(BK31:BV31),"") -> 342.5 | M33: =IF(IFERROR(M31/M$8,"")=0,"",IFERROR(M31/M$8,"")) -> 0.54545455 | N33: =IF(IFERROR(N31/N$8,"")=0,"",IFERROR(N31/N$8,"")) -> 1.2888889 | O33: =IF(IFERROR(O31/O$8,"")=0,"",IFERROR(O31/O$8,"")) -> 2.1666667 | P33: =IF(IFERROR(P31/P$8,"")=0,"",IFERROR(P31/P$8,"")) -> 1.25 | Q33: =IF(IFERROR(Q31/Q$8,"")=0,"",IFERROR(Q31/Q$8,"")) -> 11.361702 | R33: =IF(IFERROR(R31/R$8,"")=0,"",IFERROR(R31/R$8,"")) -> 10.913043 | S33: =IF(IFERROR(S31/S$8,"")=0,"",IFERROR(S31/S$8,"")) -> 19.813953 | T33: =IF(IFERROR(T31/T$8,"")=0,"",IFERROR(T31/T$8,"")) -> 25.813953 | ... AX33: =IF(IFERROR(AX31/AX$8,"")=0,"",IFERROR(AX31/AX$8,"")) -> 13.75 | AZ33: 10.358974 | BA33: 11.875 | BB33: 20.958333 | BC33: 18.769231 | BD33: 15.375 | BE33: 23.755102 | BF33: 17.869565 | BG33: 21.238095 | BH33: 15.47619 | BI33: 13.25 | BJ33: 16.44898 | BK33: 13.863636 | BL33: 15.9 | BM33: 19.043478 | BN33: 15.87234 | BO33: 12.173913 | BS33: 15.860465 | BX33: 11.9 | BZ33: 11.333333 | CA33: 12.363636
C34: 라 전월 대비 | G34: =IF(COUNT(O32:Z32)<12,"",G31-F31) -> 4259 | H34: =IF(COUNT(AA32:AL32)<12,"",H31-G31) -> -1103 | I34: =IF(COUNT(AM32:AX32)<12,"",I31-H31) -> 983 | K34: =IF(COUNT(BK32:BV32)<12,"",K31-I31) | N34: =IF(N31="","",N31-M31) -> 23 | O34: =IF(O31="","",O31-N31) -> 23 | P34: =IF(P31="","",P31-O31) -> -22 | Q34: =IF(Q31="","",Q31-P31) -> 237 | R34: =IF(R31="","",R31-Q31) -> -16 | S34: =IF(S31="","",S31-R31) -> 175 | T34: =IF(T31="","",T31-S31) -> 129 | U34: =IF(U31="","",U31-T31) -> -176 | ... AL34: =IF(AL31="","",AL31-AK31) -> 29 | AM34: =IF(AM31="","",AM31-Z31) -> -214 | AN34: =IF(AN31="","",AN31-AM31) -> 122 | AO34: =IF(AO31="","",AO31-AN31) -> 76 | AP34: =IF(AP31="","",AP31-AO31) -> 29 | AQ34: =IF(AQ31="","",AQ31-AP31) -> -156 | AR34: =IF(AR31="","",AR31-AQ31) -> 18 | AS34: =IF(AS31="","",AS31-AR31) -> 60 | AT34: =IF(AT31="","",AT31-AS31) -> -34 | AU34: =IF(AU31="","",AU31-AT31) -> -51 | ... AX34: =IF(AX31="","",AX31-AW31) -> 113 | AY34: -183 | AZ34: 202 | BA34: 83 | BB34: 218 | BC34: -137 | BD34: 3 | BE34: 213 | BF34: -171 | BG34: 35 | BH34: -121 | BI34: -7 | BJ34: 85

Sheet 통계
A1: 2026. 7. 10 | B1: 2026 | C1: 7 | M1: 46204 | N1: 46205 | O1: 46206 | P1: 46207 | Q1: 46208 | R1: 46209 | S1: 46210 | T1: 46211 | U1: 46212 | V1: 46213 | W1: 46214 | X1: 46215 | Y1: 46216 | Z1: 46217 | AA1: 46218 | AB1: 46219 | AC1: 46220 | AD1: 46221 | AE1: 46222 | AF1: 46223 | AG1: 46224 | AH1: 46225 | AI1: 46226 | AJ1: 46227 | AK1: 46228 | AL1: 46229 | AM1: 46230 | AN1: 46231 | AO1: 46232 | AP1: 46233 | AQ1: 46234
B4: 1. 서비스 운영 현황
B5: 구분 | D5: 총 접수 & 비중 | I5: 주차별 | AA5: 일자별
G6: 1 | H6: 2 | I6: 3 | J6: 4 | K6: 5 | M6: 1 | N6: 2 | O6: 3 | P6: 4 | Q6: 5 | R6: 6 | S6: 7 | T6: 8 | U6: 9 | V6: 10 | W6: 11 | X6: 12 | Y6: 13 | Z6: 14 | AA6: 15 | AB6: 16 | AC6: 17 | AD6: 18 | AE6: 19 | AF6: 20 | AG6: 21 | AH6: 22 | AI6: 23 | AJ6: 24 | AK6: 25 | AL6: 26 | AM6: 27 | AN6: 28 | AO6: 29 | AP6: 30 | AQ6: 31
B7: 영업일 | D7: 7.5 | G7: 3.5 | H7: 4 | I7: 0 | J7: 0 | K7: 0 | M7: 수 | N7: 목 | O7: 금 | P7: 토 | Q7: 일 | R7: 월 | S7: 화 | T7: 수 | U7: 목 | V7: 금 | W7: 토 | X7: 일 | Y7: 월 | Z7: 화 | AA7: 수 | AB7: 목 | AC7: 금 | AD7: 토 | AE7: 일 | AF7: 월 | AG7: 화 | AH7: 수 | AI7: 목 | AJ7: 금 | AK7: 토 | AL7: 일 | AM7: 월 | AN7: 화 | AO7: 수 | AP7: 목 | AQ7: 금
B8: 총 접수 | C8: CSONE서울1센터 | D8: 150 | E8: 0.21 | G8: 69 | H8: 81 | I8: 0 | J8: 0 | K8: 0 | M8: 19 | N8: 17 | O8: 21 | P8: 10 | Q8: 2 | R8: 20 | S8: 25 | T8: 19 | U8: 17 | V8: 0 | W8: 0 | X8: 0 | Y8: 0 | Z8: 0 | AA8: 0 | AB8: 0 | AC8: 0 | AD8: 0 | AE8: 0 | AF8: 0 | AG8: 0 | AH8: 0 | AI8: 0 | AJ8: 0 | AK8: 0 | AL8: 0 | AM8: 0 | AN8: 0 | AO8: 0 | AP8: 0 | AQ8: 0
C9: LB휴넷서울센터 | D9: 108 | E9: 0.15 | G9: 56 | H9: 52 | I9: 0 | J9: 0 | K9: 0 | M9: 16 | N9: 17 | O9: 17 | P9: 5 | Q9: 1 | R9: 13 | S9: 10 | T9: 12 | U9: 17 | V9: 0 | W9: 0 | X9: 0 | Y9: 0 | Z9: 0 | AA9: 0 | AB9: 0 | AC9: 0 | AD9: 0 | AE9: 0 | AF9: 0 | AG9: 0 | AH9: 0 | AI9: 0 | AJ9: 0 | AK9: 0 | AL9: 0 | AM9: 0 | AN9: 0 | AO9: 0 | AP9: 0 | AQ9: 0
C10: CSONE부산1센터 | D10: 120 | E10: 0.17 | G10: 56 | H10: 64 | I10: 0 | J10: 0 | K10: 0 | M10: 16 | N10: 11 | O10: 22 | P10: 7 | Q10: 0 | R10: 18 | S10: 16 | T10: 12 | U10: 18 | V10: 0 | W10: 0 | X10: 0 | Y10: 0 | Z10: 0 | AA10: 0 | AB10: 0 | AC10: 0 | AD10: 0 | AE10: 0 | AF10: 0 | AG10: 0 | AH10: 0 | AI10: 0 | AJ10: 0 | AK10: 0 | AL10: 0 | AM10: 0 | AN10: 0 | AO10: 0 | AP10: 0 | AQ10: 0
C11: CSONE부산2센터 | D11: 117 | E11: 0.16 | G11: 54 | H11: 63 | I11: 0 | J11: 0 | K11: 0 | M11: 17 | N11: 14 | O11: 14 | P11: 9 | Q11: 0 | R11: 22 | S11: 10 | T11: 13 | U11: 18 | V11: 0 | W11: 0 | X11: 0 | Y11: 0 | Z11: 0 | AA11: 0 | AB11: 0 | AC11: 0 | AD11: 0 | AE11: 0 | AF11: 0 | AG11: 0 | AH11: 0 | AI11: 0 | AJ11: 0 | AK11: 0 | AL11: 0 | AM11: 0 | AN11: 0 | AO11: 0 | AP11: 0 | AQ11: 0
C12: LB휴넷전주센터 | D12: 163 | E12: 0.22 | G12: 80 | H12: 88 | I12: 0 | J12: 0 | K12: 0 | M12: 30 | N12: 20 | O12: 19 | P12: 9 | Q12: 2 | R12: 21 | S12: 25 | T12: 19 | U12: 23 | V12: 0 | W12: 0 | X12: 0 | Y12: 0 | Z12: 0 | AA12: 0 | AB12: 0 | AC12: 0 | AD12: 0 | AE12: 0 | AF12: 0 | AG12: 0 | AH12: 0 | AI12: 0 | AJ12: 0 | AK12: 0 | AL12: 0 | AM12: 0 | AN12: 0 | AO12: 0 | AP12: 0 | AQ12: 0
C13: 홈매니저 | D13: 62 | E13: 0.09 | G13: 32 | H13: 30 | I13: 0 | J13: 0 | K13: 0 | M13: 10 | N13: 7 | O13: 13 | P13: 2 | Q13: 0 | R13: 13 | S13: 3 | T13: 11 | U13: 3 | V13: 0 | W13: 0 | X13: 0 | Y13: 0 | Z13: 0 | AA13: 0 | AB13: 0 | AC13: 0 | AD13: 0 | AE13: 0 | AF13: 0 | AG13: 0 | AH13: 0 | AI13: 0 | AJ13: 0 | AK13: 0 | AL13: 0 | AM13: 0 | AN13: 0 | AO13: 0 | AP13: 0 | AQ13: 0
C14: 기타 | D14: 6 | E14: 0.01 | G14: 1 | H14: 0 | I14: 0 | J14: 0 | K14: 0 | M14: 1 | N14: 0 | O14: 0 | P14: 0 | Q14: 0 | R14: 0 | S14: 0 | T14: 0 | U14: 0 | V14: 0 | W14: 0 | X14: 0 | Y14: 0 | Z14: 0 | AA14: 0 | AB14: 0 | AC14: 0 | AD14: 0 | AE14: 0 | AF14: 0 | AG14: 0 | AH14: 0 | AI14: 0 | AJ14: 0 | AK14: 0 | AL14: 0 | AM14: 0 | AN14: 0 | AO14: 0 | AP14: 0 | AQ14: 0
B15: 소계 | D15: 726 | E15: 1 | G15: 348 | H15: 378 | I15: 0 | J15: 0 | K15: 0 | M15: 109 | N15: 86 | O15: 106 | P15: 42 | Q15: 5 | R15: 107 | S15: 89 | T15: 86 | U15: 96 | V15: 0 | W15: 0 | X15: 0 | Y15: 0 | Z15: 0 | AA15: 0 | AB15: 0 | AC15: 0 | AD15: 0 | AE15: 0 | AF15: 0 | AG15: 0 | AH15: 0 | AI15: 0 | AJ15: 0 | AK15: 0 | AL15: 0 | AM15: 0 | AN15: 0 | AO15: 0 | AP15: 0 | AQ15: 0
B16: 방문A/S 접수 | C16: CSONE서울1센터 | D16: 14 | E16: 0.09 | G16: 6 | H16: 8 | I16: 0 | J16: 0 | K16: 0 | M16: 1 | N16: 3 | O16: 2 | P16: 0 | Q16: 0 | R16: 2 | S16: 2 | T16: 3 | U16: 1 | V16: 0 | W16: 0 | X16: 0 | Y16: 0 | Z16: 0 | AA16: 0 | AB16: 0 | AC16: 0 | AD16: 0 | AE16: 0 | AF16: 0 | AG16: 0 | AH16: 0 | AI16: 0 | AJ16: 0 | AK16: 0 | AL16: 0 | AM16: 0 | AN16: 0 | AO16: 0 | AP16: 0 | AQ16: 0
C17: LB휴넷서울센터 | D17: 6 | E17: 0.06 | G17: 1 | H17: 5 | I17: 0 | J17: 0 | K17: 0 | M17: 0 | N17: 0 | O17: 1 | P17: 0 | Q17: 0 | R17: 2 | S17: 0 | T17: 1 | U17: 2 | V17: 0 | W17: 0 | X17: 0 | Y17: 0 | Z17: 0 | AA17: 0 | AB17: 0 | AC17: 0 | AD17: 0 | AE17: 0 | AF17: 0 | AG17: 0 | AH17: 0 | AI17: 0 | AJ17: 0 | AK17: 0 | AL17: 0 | AM17: 0 | AN17: 0 | AO17: 0 | AP17: 0 | AQ17: 0
C18: CSONE부산1센터 | D18: 14 | E18: 0.12 | G18: 6 | H18: 8 | I18: 0 | J18: 0 | K18: 0 | M18: 2 | N18: 1 | O18: 3 | P18: 0 | Q18: 0 | R18: 3 | S18: 3 | T18: 2 | U18: 0 | V18: 0 | W18: 0 | X18: 0 | Y18: 0 | Z18: 0 | AA18: 0 | AB18: 0 | AC18: 0 | AD18: 0 | AE18: 0 | AF18: 0 | AG18: 0 | AH18: 0 | AI18: 0 | AJ18: 0 | AK18: 0 | AL18: 0 | AM18: 0 | AN18: 0 | AO18: 0 | AP18: 0 | AQ18: 0
C19: CSONE부산2센터 | D19: 14 | E19: 0.12 | G19: 6 | H19: 8 | I19: 0 | J19: 0 | K19: 0 | M19: 2 | N19: 2 | O19: 1 | P19: 1 | Q19: 0 | R19: 4 | S19: 0 | T19: 1 | U19: 3 | V19: 0 | W19: 0 | X19: 0 | Y19: 0 | Z19: 0 | AA19: 0 | AB19: 0 | AC19: 0 | AD19: 0 | AE19: 0 | AF19: 0 | AG19: 0 | AH19: 0 | AI19: 0 | AJ19: 0 | AK19: 0 | AL19: 0 | AM19: 0 | AN19: 0 | AO19: 0 | AP19: 0 | AQ19: 0
C20: LB휴넷전주센터 | D20: 20 | E20: 0.12 | G20: 7 | H20: 13 | I20: 0 | J20: 0 | K20: 0 | M20: 2 | N20: 3 | O20: 2 | P20: 0 | Q20: 0 | R20: 5 | S20: 1 | T20: 2 | U20: 5 | V20: 0 | W20: 0 | X20: 0 | Y20: 0 | Z20: 0 | AA20: 0 | AB20: 0 | AC20: 0 | AD20: 0 | AE20: 0 | AF20: 0 | AG20: 0 | AH20: 0 | AI20: 0 | AJ20: 0 | AK20: 0 | AL20: 0 | AM20: 0 | AN20: 0 | AO20: 0 | AP20: 0 | AQ20: 0
B21: 소계 | D21: 69 | E21: 0.1 | G21: 26 | H21: 43 | I21: 0 | J21: 0 | K21: 0 | M21: 7 | N21: 9 | O21: 9 | P21: 1 | Q21: 0 | R21: 17 | S21: 6 | T21: 9 | U21: 11 | V21: 0 | W21: 0 | X21: 0 | Y21: 0 | Z21: 0 | AA21: 0 | AB21: 0 | AC21: 0 | AD21: 0 | AE21: 0 | AF21: 0 | AG21: 0 | AH21: 0 | AI21: 0 | AJ21: 0 | AK21: 0 | AL21: 0 | AM21: 0 | AN21: 0 | AO21: 0 | AP21: 0 | AQ21: 0
B22: 방문 A/S 접수 비율 | D22: 0.46 | G22: 0.0747 | H22: 0.1138 | M22: 0.0642 | N22: 0.1047 | O22: 0.0849 | P22: 0.0238 | Q22: 0 | R22: 0.1589 | S22: 0.0674 | T22: 0.1047 | U22: 0.1146
B24: 2. 센터별 접수 통계
B25: 센터 | C25: 팀 | D25: 총접수 & 비중 | G25: 1 | H25: 2 | I25: 3 | J25: 4 | K25: 5 | M25: 1 | N25: 2 | O25: 3 | P25: 4 | Q25: 5 | R25: 6 | S25: 7 | T25: 8 | U25: 9 | V25: 10 | W25: 11 | X25: 12 | Y25: 13 | Z25: 14 | AA25: 15 | AB25: 16 | AC25: 17 | AD25: 18 | AE25: 19 | AF25: 20 | AG25: 21 | AH25: 22 | AI25: 23 | AJ25: 24 | AK25: 25 | AL25: 26 | AM25: 27 | AN25: 28 | AO25: 29 | AP25: 30 | AQ25: 31
B26: CSONE서울1센터 | C26: 기술1팀 | D26: 0 | E26: 0 | G26: 24 | H26: 32 | I26: 0 | J26: 0 | K26: 0 | M26: 7 | N26: 7 | O26: 5 | P26: 3 | Q26: 2 | R26: 8 | S26: 11 | T26: 7 | U26: 6 | V26: 0 | W26: 0 | X26: 0 | Y26: 0 | Z26: 0 | AA26: 0 | AB26: 0 | AC26: 0 | AD26: 0 | AE26: 0 | AF26: 0 | AG26: 0 | AH26: 0 | AI26: 0 | AJ26: 0 | AK26: 0 | AL26: 0 | AM26: 0 | AN26: 0 | AO26: 0 | AP26: 0 | AQ26: 0
B27: CSONE서울*1센터 | C27: 기술2팀 | D27: 1 | E27: 0.01 | G27: 0 | H27: 1 | I27: 0 | J27: 0 | K27: 0 | M27: 0 | N27: 0 | O27: 0 | P27: 0 | Q27: 0 | R27: 0 | S27: 0 | T27: 0 | U27: 1 | V27: 0 | W27: 0 | X27: 0 | Y27: 0 | Z27: 0 | AA27: 0 | AB27: 0 | AC27: 0 | AD27: 0 | AE27: 0 | AF27: 0 | AG27: 0 | AH27: 0 | AI27: 0 | AJ27: 0 | AK27: 0 | AL27: 0 | AM27: 0 | AN27: 0 | AO27: 0 | AP27: 0 | AQ27: 0
B28: CSONE서울*1센터 | C28: 기술3팀 | D28: 0 | E28: 0 | G28: 0 | H28: 0 | I28: 0 | J28: 0 | K28: 0 | M28: 0 | N28: 0 | O28: 0 | P28: 0 | Q28: 0 | R28: 0 | S28: 0 | T28: 0 | U28: 0 | V28: 0 | W28: 0 | X28: 0 | Y28: 0 | Z28: 0 | AA28: 0 | AB28: 0 | AC28: 0 | AD28: 0 | AE28: 0 | AF28: 0 | AG28: 0 | AH28: 0 | AI28: 0 | AJ28: 0 | AK28: 0 | AL28: 0 | AM28: 0 | AN28: 0 | AO28: 0 | AP28: 0 | AQ28: 0
B29: CSONE서울*1센터 | C29: 기술 맞춤제안1팀 | D29: 33 | E29: 0.22 | G29: 22 | H29: 11 | I29: 0 | J29: 0 | K29: 0 | M29: 6 | N29: 4 | O29: 12 | P29: 0 | Q29: 0 | R29: 1 | S29: 3 | T29: 3 | U29: 4 | V29: 0 | W29: 0 | X29: 0 | Y29: 0 | Z29: 0 | AA29: 0 | AB29: 0 | AC29: 0 | AD29: 0 | AE29: 0 | AF29: 0 | AG29: 0 | AH29: 0 | AI29: 0 | AJ29: 0 | AK29: 0 | AL29: 0 | AM29: 0 | AN29: 0 | AO29: 0 | AP29: 0 | AQ29: 0
B30: CSONE서울*1센터 | C30: 멀티상담1팀 | D30: 30 | E30: 0.2 | G30: 11 | H30: 19 | I30: 0 | J30: 0 | K30: 0 | M30: 3 | N30: 1 | O30: 4 | P30: 3 | Q30: 0 | R30: 6 | S30: 7 | T30: 3 | U30: 3 | V30: 0 | W30: 0 | X30: 0 | Y30: 0 | Z30: 0 | AA30: 0 | AB30: 0 | AC30: 0 | AD30: 0 | AE30: 0 | AF30: 0 | AG30: 0 | AH30: 0 | AI30: 0 | AJ30: 0 | AK30: 0 | AL30: 0 | AM30: 0 | AN30: 0 | AO30: 0 | AP30: 0 | AQ30: 0
B31: CSONE서울*1센터 | C31: 멀티상담2팀 | D31: 25 | E31: 0.17 | G31: 10 | H31: 15 | I31: 0 | J31: 0 | K31: 0 | M31: 2 | N31: 4 | O31: 0 | P31: 4 | Q31: 0 | R31: 5 | S31: 4 | T31: 4 | U31: 2 | V31: 0 | W31: 0 | X31: 0 | Y31: 0 | Z31: 0 | AA31: 0 | AB31: 0 | AC31: 0 | AD31: 0 | AE31: 0 | AF31: 0 | AG31: 0 | AH31: 0 | AI31: 0 | AJ31: 0 | AK31: 0 | AL31: 0 | AM31: 0 | AN31: 0 | AO31: 0 | AP31: 0 | AQ31: 0
B32: CSONE서울*1센터 | C32: 기술A1팀 | D32: 0 | E32: 0 | G32: 0 | H32: 0 | I32: 0 | J32: 0 | K32: 0 | M32: 0 | N32: 0 | O32: 0 | P32: 0 | Q32: 0 | R32: 0 | S32: 0 | T32: 0 | U32: 0 | V32: 0 | W32: 0 | X32: 0 | Y32: 0 | Z32: 0 | AA32: 0 | AB32: 0 | AC32: 0 | AD32: 0 | AE32: 0 | AF32: 0 | AG32: 0 | AH32: 0 | AI32: 0 | AJ32: 0 | AK32: 0 | AL32: 0 | AM32: 0 | AN32: 0 | AO32: 0 | AP32: 0 | AQ32: 0
B33: CSONE서울*1센터 | C33: 기술A2팀 | D33: 0 | E33: 0 | G33: 0 | H33: 0 | I33: 0 | J33: 0 | K33: 0 | M33: 0 | N33: 0 | O33: 0 | P33: 0 | Q33: 0 | R33: 0 | S33: 0 | T33: 0 | U33: 0 | V33: 0 | W33: 0 | X33: 0 | Y33: 0 | Z33: 0 | AA33: 0 | AB33: 0 | AC33: 0 | AD33: 0 | AE33: 0 | AF33: 0 | AG33: 0 | AH33: 0 | AI33: 0 | AJ33: 0 | AK33: 0 | AL33: 0 | AM33: 0 | AN33: 0 | AO33: 0 | AP33: 0 | AQ33: 0
B34: CSONE서울*1센터 | C34: 기타 | D34: 61 | E34: 0.41 | G34: 2 | H34: 3 | I34: 0 | J34: 0 | K34: 0 | L34: 0 | M34: 1 | N34: 1 | O34: 0 | P34: 0 | Q34: 0 | R34: 0 | S34: 0 | T34: 2 | U34: 1 | V34: 0 | W34: 0 | X34: 0 | Y34: 0 | Z34: 0 | AA34: 0 | AB34: 0 | AC34: 0 | AD34: 0 | AE34: 0 | AF34: 0 | AG34: 0 | AH34: 0 | AI34: 0 | AJ34: 0 | AK34: 0 | AL34: 0 | AM34: 0 | AN34: 0 | AO34: 0 | AP34: 0 | AQ34: 0
B35: CSONE서울*1센터 | C35: 소계 | D35: 150 | E35: 1 | G35: 69 | H35: 81 | I35: 0 | J35: 0 | K35: 0 | M35: 19 | N35: 17 | O35: 21 | P35: 10 | Q35: 2 | R35: 20 | S35: 25 | T35: 19 | U35: 17 | V35: 0 | W35: 0 | X35: 0 | Y35: 0 | Z35: 0 | AA35: 0 | AB35: 0 | AC35: 0 | AD35: 0 | AE35: 0 | AF35: 0 | AG35: 0 | AH35: 0 | AI35: 0 | AJ35: 0 | AK35: 0 | AL35: 0 | AM35: 0 | AN35: 0 | AO35: 0 | AP35: 0 | AQ35: 0
B36: LB휴넷서울센터 | C36: 기술1팀 | D36: 22 | E36: 0.2 | G36: 11 | H36: 11 | I36: 0 | J36: 0 | K36: 0 | M36: 3 | N36: 3 | O36: 3 | P36: 1 | Q36: 1 | R36: 3 | S36: 2 | T36: 3 | U36: 3 | V36: 0 | W36: 0 | X36: 0 | Y36: 0 | Z36: 0 | AA36: 0 | AB36: 0 | AC36: 0 | AD36: 0 | AE36: 0 | AF36: 0 | AG36: 0 | AH36: 0 | AI36: 0 | AJ36: 0 | AK36: 0 | AL36: 0 | AM36: 0 | AN36: 0 | AO36: 0 | AP36: 0 | AQ36: 0
B37: LB휴넷서울센터 | C37: 기술2팀 | D37: 0 | E37: 0 | G37: 0 | H37: 0 | I37: 0 | J37: 0 | K37: 0 | M37: 0 | N37: 0 | O37: 0 | P37: 0 | Q37: 0 | R37: 0 | S37: 0 | T37: 0 | U37: 0 | V37: 0 | W37: 0 | X37: 0 | Y37: 0 | Z37: 0 | AA37: 0 | AB37: 0 | AC37: 0 | AD37: 0 | AE37: 0 | AF37: 0 | AG37: 0 | AH37: 0 | AI37: 0 | AJ37: 0 | AK37: 0 | AL37: 0 | AM37: 0 | AN37: 0 | AO37: 0 | AP37: 0 | AQ37: 0
B38: LB휴넷서울센터 | C38: 기술3팀 | D38: 1 | E38: 0.01 | G38: 1 | H38: 0 | I38: 0 | J38: 0 | K38: 0 | M38: 0 | N38: 1 | O38: 0 | P38: 0 | Q38: 0 | R38: 0 | S38: 0 | T38: 0 | U38: 0 | V38: 0 | W38: 0 | X38: 0 | Y38: 0 | Z38: 0 | AA38: 0 | AB38: 0 | AC38: 0 | AD38: 0 | AE38: 0 | AF38: 0 | AG38: 0 | AH38: 0 | AI38: 0 | AJ38: 0 | AK38: 0 | AL38: 0 | AM38: 0 | AN38: 0 | AO38: 0 | AP38: 0 | AQ38: 0
B39: LB휴넷서울센터 | C39: 기술4팀 | D39: 0 | E39: 0 | G39: 0 | H39: 0 | I39: 0 | J39: 0 | K39: 0 | M39: 0 | N39: 0 | O39: 0 | P39: 0 | Q39: 0 | R39: 0 | S39: 0 | T39: 0 | U39: 0 | V39: 0 | W39: 0 | X39: 0 | Y39: 0 | Z39: 0 | AA39: 0 | AB39: 0 | AC39: 0 | AD39: 0 | AE39: 0 | AF39: 0 | AG39: 0 | AH39: 0 | AI39: 0 | AJ39: 0 | AK39: 0 | AL39: 0 | AM39: 0 | AN39: 0 | AO39: 0 | AP39: 0 | AQ39: 0
B40: LB휴넷서울센터 | C40: 기술A1팀 | D40: 0 | E40: 0 | G40: 0 | H40: 0 | I40: 0 | J40: 0 | K40: 0 | M40: 0 | N40: 0 | O40: 0 | P40: 0 | Q40: 0 | R40: 0 | S40: 0 | T40: 0 | U40: 0 | V40: 0 | W40: 0 | X40: 0 | Y40: 0 | Z40: 0 | AA40: 0 | AB40: 0 | AC40: 0 | AD40: 0 | AE40: 0 | AF40: 0 | AG40: 0 | AH40: 0 | AI40: 0 | AJ40: 0 | AK40: 0 | AL40: 0 | AM40: 0 | AN40: 0 | AO40: 0 | AP40: 0 | AQ40: 0
B41: LB휴넷서울센터 | C41: 기술A2팀 | D41: 0 | E41: 0 | G41: 0 | H41: 0 | I41: 0 | J41: 0 | K41: 0 | M41: 0 | N41: 0 | O41: 0 | P41: 0 | Q41: 0 | R41: 0 | S41: 0 | T41: 0 | U41: 0 | V41: 0 | W41: 0 | X41: 0 | Y41: 0 | Z41: 0 | AA41: 0 | AB41: 0 | AC41: 0 | AD41: 0 | AE41: 0 | AF41: 0 | AG41: 0 | AH41: 0 | AI41: 0 | AJ41: 0 | AK41: 0 | AL41: 0 | AM41: 0 | AN41: 0 | AO41: 0 | AP41: 0 | AQ41: 0
B42: LB휴넷서울센터 | C42: 멀티상담1팀 | D42: 32 | E42: 0.3 | G42: 18 | H42: 14 | I42: 0 | J42: 0 | K42: 0 | M42: 4 | N42: 8 | O42: 6 | P42: 0 | Q42: 0 | R42: 4 | S42: 1 | T42: 1 | U42: 8 | V42: 0 | W42: 0 | X42: 0 | Y42: 0 | Z42: 0 | AA42: 0 | AB42: 0 | AC42: 0 | AD42: 0 | AE42: 0 | AF42: 0 | AG42: 0 | AH42: 0 | AI42: 0 | AJ42: 0 | AK42: 0 | AL42: 0 | AM42: 0 | AN42: 0 | AO42: 0 | AP42: 0 | AQ42: 0
B43: LB휴넷서울센터 | C43: 멀티상담2팀 | D43: 24 | E43: 0.22 | G43: 9 | H43: 15 | I43: 0 | J43: 0 | K43: 0 | M43: 2 | N43: 1 | O43: 4 | P43: 2 | Q43: 0 | R43: 3 | S43: 3 | T43: 5 | U43: 4 | V43: 0 | W43: 0 | X43: 0 | Y43: 0 | Z43: 0 | AA43: 0 | AB43: 0 | AC43: 0 | AD43: 0 | AE43: 0 | AF43: 0 | AG43: 0 | AH43: 0 | AI43: 0 | AJ43: 0 | AK43: 0 | AL43: 0 | AM43: 0 | AN43: 0 | AO43: 0 | AP43: 0 | AQ43: 0
...

Sheet 고객만족후기
A1: No. | B1: 접수일자 | C1: 접수시간 | D1: 리뷰점수 | E1: 리뷰
A2: 1 | B2: 45748 | C2: 0.9093287 | D2: 10 | E2: 늦은 시간에 친절하게 작업 해 주셔서 감사합니다.
A3: 2 | B3: 45748 | C3: 0.88916667 | D3: 10 | E3: 감사합니다
A4: 3 | B4: 45748 | C4: 0.83275463 | D4: 10 | E4: 빠르고 친절한 답변, 처리도 매우 빠르게 진행해주셨습니다.
A5: 4 | B5: 45748 | C5: 0.82505787 | D5: 10 | E5: 신속하게 정확하게 진단을 해주셔서 좋았습니다.
A6: 5 | B6: 45748 | C6: 0.81509259 | D6: 10 | E6: 기사님 친절하시고 잘 이해할수 있도록 설명해주셨습니다.
A7: 6 | B7: 45748 | C7: 0.7772338 | D7: 10 | E7: 친절하고 빠르고 아주 좋앗습니다.
A8: 7 | B8: 45748 | C8: 0.76637731 | D8: 10 | E8: 궁금한 것도 친절히 알려주시고, 감사하네요~ 막히면 바로 연락 드려서 또 서비스 받고 싶고... 아 그러면 너무 피곤해지시려나요? ㅎ 원활하게 해결해 주셔서 감사드립니다~ 꾸벅 (-.-)(_ _)
A9: 8 | B9: 45748 | C9: 0.75304398 | D9: 10 | E9: 꼼꼼하게 잘 체크해주셨습니다.
A10: 9 | B10: 45748 | C10: 0.72349537 | D10: 10 | E10: 엉청 친절하시고 이유 설명을 잘 해주십니다
A11: 10 | B11: 45748 | C11: 0.7196875 | D11: 10 | E11: 친절한 설명 감사합니다^^
A12: 11 | B12: 45748 | C12: 0.70418981 | D12: 10 | E12: 원격조정 해주신 기사님분께서 빠르게 원인을 찾아주시고 친절하게 설명주셔서 문제점을 해결할 수 있었습니다. 최고
A13: 12 | B13: 45748 | C13: 0.7028588 | D13: 10 | E13: 아주 친절하고 세심하게 설명을 잘 해주셨습니다. 빠른 대응 감사합니다.
... A500: 499 | B500: 45762 | C500: 0.41516204 | D500: 10 | E500: 컴퓨터가 느려 검진을 받았는데 하나 하나 설명을 잘 해 주시고 처리해 주셔서 너무 감사합니다. 모르는 프로그램도 다 제거해주시고 속도가 빨라지는 것 까지 확인해 주시고 전화를 끊으셔도 너무너무 감사했습니다. LG를 20년 넘게 써 왔는데 오늘도 너무 쁘듯하네요. 좋은 하루 되세요
A501: =ROW()-1 -> 500 | B501: 45763 | C501: 0.91290509 | D501: 10 | E501: 원격지원센타 성심성의것 봐주시네요^^
A502: =ROW()-1 -> 501 | B502: 45763 | C502: 0.8956713 | D502: 10 | E502: 아주 좋습니다. 이런 서비스가 적극적으로 해줫으면 좋겟습니다. 고센에서 시간을 너무 잡아 먹습니다 해결 안될거 같으면 진작 원격센터로 연결해줫으면 빨리 해결 됫을거를..
A503: =ROW()-1 -> 502 | B503: 45763 | C503: 0.88576389 | D503: 10 | E503: 빠른 원격및 처리로 인해 매우 만족 합니다. 허나 늦은 저녁 101 유선 연결시 원활하지 않은부분이 조금 아쉽운 부분입니다.
A504: =ROW()-1 -> 503 | B504: 45763 | C504: 0.8584838 | D504: 10 | E504: 너무너무 친절하시고 궁금한점 문제해결 다 해주셨어요 최고최고 완전최고 !!!!
A505: =ROW()-1 -> 504 | B505: 45763 | C505: 0.83939815 | D505: 10 | E505: 친절한 서비스 감사합니다 항상 행복하시길 기원합니다
A506: =ROW()-1 -> 505 | B506: 45763 | C506: 0.83958333 | D506: 10 | E506: 늦은 시간 빠르게 해결해주어 빨리 총질하러 갑니다! 감사합니다!
A507: =ROW()-1 -> 506 | B507: 45763 | C507: 0.83041667 | D507: 10 | E507: 간단한 작업이엇지만 정말 도움이 많이 됐습니다 감사합니다 !!!!
A508: =ROW()-1 -> 507 | B508: 45763 | C508: 0.78920139 | D508: 10 | E508: 친절한 상담 감사함니다
A509: =ROW()-1 -> 508 | B509: 45763 | C509: 0.75027778 | D509: 10 | E509: 잘 해주셔서 감사합니다
A510: =ROW()-1 -> 509 | B510: 45763 | C510: 0.74763889 | D510: 10 | E510: 쏙쏙 이해하기 쉽게 설명을 해주셔서 10년 묵은 체증이 내려간 느낌입니다. 너무 감사해요!^^ 제 궁금증 전부를 알려주시기에는 원격 시스템이 한계가 있었을텐데, 최대한 알려주시려고 노력하셨고, 덕분에 쉽게 해결이 되었네요. 역시 서비스는 LG가 최고입니다. 기사님 최고에요*^^*
A511: =ROW()-1 -> 510 | B511: 45763 | C511: 0.74048611 | D511: 10 | E511: 친절하게 잘 상담 받았습니다.
A512: =ROW()-1 -> 511 | B512: 45763 | C512: 0.72493056 | D512: 10 | E512: 서비스만족합니다.
... A809: =ROW()-1 -> 808 | B809: 45771 | C809: 0.47777778 | D809: 10 | E809: 친절하게 점검 후 필요한 사항에 대한 후속조치까지 깔끔하고 빠르게 진행해주셧습니다. 감사합니다~
A810: =ROW()-1 -> 809 | B810: 45771 | C810: 0.47755787 | D810: 10
A811: =ROW()-1 -> 810 | B811: 45771 | C811: 0.46655093 | D811: 10 | E811: 감사합니다
A812: =ROW()-1 -> 811 | B812: 45771 | C812: 0.45545139 | D812: 10 | E812: 하나 부터 열까지 자세히 알려주시고 도움 많이 주셨습니다. 엄청 친절하십니다~ 요청한 점검이외에도 다양한 부분에서 도움주셔서 정말 감사했습니다~ 좋은 하루 되시길 바래요.
A813: =ROW()-1 -> 812 | B813: 45771 | C813: 0.43262731 | D813: 9 | E813: 친절하게 잘 설명해 주심
A814: =ROW()-1 -> 813 | B814: 45771 | C814: 0.43209491 | D814: 10 | E814: 빠른확인과 신속한 조치로 만점드립니다 굿!!
A815: =ROW()-1 -> 814 | B815: 45771 | C815: 0.4290625 | D815: 10 | E815: 친절하게 대응해주시고 바로바로 문제점 알려주시면서 잘 대처방안을 제시해주셔서 너무 감사합니다
A816: =ROW()-1 -> 815 | B816: 45771 | C816: 0.40712963 | D816: 10 | E816: 최고의 서비스를 해주셨습니다...몇 달간 사용하지못했던 무선프린터 설정 문제를 해결해주셨습니다.
A817: =ROW()-1 -> 816 | B817: 45771 | C817: 0.39600694 | D817: 10 | E817: 친절한 상담 감사합니다
A818: =ROW()-1 -> 817 | B818: 45771 | C818: 0.3897338 | D818: 10 | E818: 정확하고빠르게처리되었습니다.만족합니다
A819: =ROW()-1 -> 818 | B819: 45771 | C819: 0.38269676 | D819: 4 | E819: 친절하게 안내해주셨습니다
A820: =ROW()-1 -> 819 | B820: 45771 | C820: 0.38248843 | D820: 10 | E820: 네 친절하게 스마트하게 잘 하셨어요^^
A821: =ROW()-1 -> 820 | B821: 45772 | C821: 0.77619213 | D821: 10 | E821: 친절하게 잘 알려주셔서 감사합니다^^ 좋은하루 되세요!
A822: =ROW()-1 -> 821 | B822: 45772 | C822: 0.75357639 | D822: 10 | E822: 친절하게 응대해주시고 적절한 조치를 취해주셨으며 혹시 있을 문제에 어떤 방법으로 대응해야할지 안내해주셨습니다. 감사합니다!
...

Sheet 4월 통계
B1: 2025년 4월 스마트원격진단 접수 현황
B3: 1. 전체 원격점검 접수 통계
B4: 구분 | E4: 실적
E5: 1 | F5: 2 | G5: 3 | H5: 4 | I5: 5 | J5: 6 | K5: 7 | L5: 8 | M5: 9 | N5: 10 | O5: 11 | P5: 12 | Q5: 13 | R5: 14 | S5: 15 | T5: 16 | U5: 17 | V5: 18 | W5: 19 | X5: 20 | Y5: 21 | Z5: 22 | AA5: 23 | AB5: 24 | AC5: 25 | AD5: 26 | AE5: 27 | AF5: 28 | AG5: 29 | AH5: 30
E6: 45017 | F6: 45018 | G6: 45019 | H6: 45020 | I6: 45021 | J6: 45022 | K6: 45023 | L6: 45024 | M6: 45025 | N6: 45026 | O6: 45027 | P6: 45028 | Q6: 45029 | R6: 45030 | S6: 45031 | T6: 45032 | U6: 45033 | V6: 45034 | W6: 45035 | X6: 45036 | Y6: 45037 | Z6: 45038 | AA6: 45039 | AB6: 45040 | AC6: 45041 | AD6: 45042 | AE6: 45043
B7: 합계 | D7: 952 | E7: 97 | F7: 92 | G7: 100 | H7: 114 | I7: 34 | J7: 0 | K7: 103 | L7: 101 | M7: 98 | N7: 94 | O7: 95 | P7: 24
B8: CSONE서울1센터 | D8: 209 | E8: 25 | F8: 20 | G8: 27 | H8: 21 | I8: 6 | J8: 0 | K8: 25 | L8: 17 | M8: 19 | N8: 21 | O8: 21 | P8: 7
B9: LB휴넷서울센터 | D9: 180 | E9: 18 | F9: 23 | G9: 17 | H9: 26 | I9: 7 | J9: 0 | K9: 17 | L9: 17 | M9: 19 | N9: 18 | O9: 14 | P9: 4
B10: CSONE부산1센터 | D10: 160 | E10: 14 | F10: 11 | G10: 21 | H10: 19 | I10: 6 | J10: 0 | K10: 15 | L10: 19 | M10: 17 | N10: 16 | O10: 20 | P10: 2
B11: CSONE부산2센터 | D11: 148 | E11: 13 | F11: 11 | G11: 14 | H11: 22 | I11: 4 | J11: 0 | K11: 19 | L11: 17 | M11: 15 | N11: 16 | O11: 13 | P11: 4
B12: LB휴넷전주센터 | D12: 228 | E12: 23 | F12: 23 | G12: 19 | H12: 24 | I12: 10 | J12: 0 | K12: 26 | L12: 29 | M12: 23 | N12: 21 | O12: 24 | P12: 6
B13: 기타 | D13: 27 | E13: 4 | F13: 4 | G13: 2 | H13: 2 | I13: 1 | J13: 0 | K13: 1 | L13: 2 | M13: 5 | N13: 2 | O13: 3 | P13: 1
B15: 스 캔 | D15: 0
B16: AS 재접수건 | D16: 119 | E16: 15 | F16: 11 | G16: 9 | H16: 11 | I16: 5 | J16: 0 | K16: 12 | L16: 18 | M16: 14 | N16: 7 | O16: 15 | P16: 2
B18: 2. 센터별 접수 통계
B19: CSONE서울1센터 | C19: 기술1팀 | D19: 38 | E19: 5 | F19: 4 | G19: 3 | H19: 2 | I19: 1 | J19: 0 | K19: 9 | L19: 1 | M19: 2 | N19: 5 | O19: 4 | P19: 2
C20: 기술2팀 | D20: 50 | E20: 6 | F20: 5 | G20: 8 | H20: 5 | I20: 0 | J20: 0 | K20: 6 | L20: 3 | M20: 5 | N20: 6 | O20: 4 | P20: 2
C21: 기술3팀 | D21: 41 | E21: 1 | F21: 3 | G21: 6 | H21: 5 | I21: 2 | J21: 0 | K21: 3 | L21: 4 | M21: 5 | N21: 5 | O21: 4 | P21: 3
C22: 기술4팀 | D22: 0 | E22: 0 | F22: 0 | G22: 0 | H22: 0 | I22: 0 | J22: 0 | K22: 0 | L22: 0 | M22: 0 | N22: 0 | O22: 0 | P22: 0
C23: 기술5팀 | D23: 0 | E23: 0 | F23: 0 | G23: 0 | H23: 0 | I23: 0 | J23: 0 | K23: 0 | L23: 0 | M23: 0 | N23: 0 | O23: 0 | P23: 0
C24: 기술6팀 | D24: 0 | E24: 0 | F24: 0 | G24: 0 | H24: 0 | I24: 0 | J24: 0 | K24: 0 | L24: 0 | M24: 0 | N24: 0 | O24: 0 | P24: 0
C25: 기술A1 | D25: 9 | E25: 2 | F25: 0 | G25: 1 | H25: 1 | I25: 0 | J25: 0 | K25: 2 | L25: 0 | M25: 2 | N25: 1 | O25: 0 | P25: 0
C26: 기술A2 | D26: 13 | E26: 2 | F26: 2 | G26: 1 | H26: 1 | I26: 0 | J26: 0 | K26: 1 | L26: 2 | M26: 2 | N26: 0 | O26: 2 | P26: 0
C27: 기술맞춤제안1팀 | D27: 46 | E27: 8 | F27: 6 | G27: 7 | H27: 6 | I27: 0 | J27: 0 | K27: 3 | L27: 5 | M27: 3 | N27: 2 | O27: 6 | P27: 0
C28: 멀티 | D28: 9 | E28: 1 | F28: 0 | G28: 1 | H28: 1 | I28: 0 | J28: 0 | K28: 1 | L28: 2 | M28: 0 | N28: 2 | O28: 1 | P28: 0
C29: 기타 | D29: 3 | E29: 0 | F29: 0 | G29: 0 | H29: 0 | I29: 3 | J29: 0 | K29: 0 | L29: 0 | M29: 0 | N29: 0 | O29: 0 | P29: 0
B31: LB휴넷서울센터 | C31: 기술1팀 | D31: 8 | E31: 2 | F31: 0 | G31: 0 | H31: 1 | I31: 0 | J31: 0 | K31: 0 | L31: 2 | M31: 2 | N31: 1 | O31: 0 | P31: 0
C32: 기술2팀 | D32: 41 | E32: 8 | F32: 3 | G32: 5 | H32: 5 | I32: 0 | J32: 0 | K32: 6 | L32: 4 | M32: 5 | N32: 3 | O32: 2 | P32: 0
C33: 기술3팀 | D33: 62 | E33: 5 | F33: 11 | G33: 4 | H33: 10 | I33: 0 | J33: 0 | K33: 7 | L33: 6 | M33: 6 | N33: 4 | O33: 6 | P33: 3
C34: 기술4팀 | D34: 42 | E34: 2 | F34: 7 | G34: 6 | H34: 4 | I34: 4 | J34: 0 | K34: 4 | L34: 3 | M34: 2 | N34: 7 | O34: 3 | P34: 0
C35: 기술5팀 | D35: 0 | E35: 0 | F35: 0 | G35: 0 | H35: 0 | I35: 0 | J35: 0 | K35: 0 | L35: 0 | M35: 0 | N35: 0 | O35: 0 | P35: 0
C36: 기술6팀 | D36: 0 | E36: 0 | F36: 0 | G36: 0 | H36: 0 | I36: 0 | J36: 0 | K36: 0 | L36: 0 | M36: 0 | N36: 0 | O36: 0 | P36: 0
C37: 기술A1 | D37: 5 | E37: 1 | F37: 0 | G37: 2 | H37: 0 | I37: 0 | J37: 0 | K37: 0 | L37: 0 | M37: 1 | N37: 1 | O37: 0 | P37: 0
C38: 기술A2 | D38: 3 | E38: 0 | F38: 0 | G38: 0 | H38: 1 | I38: 0 | J38: 0 | K38: 0 | L38: 0 | M38: 1 | N38: 0 | O38: 1 | P38: 0
C39: 기술맞춤제안1팀 | D39: 17 | E39: 0 | F39: 2 | G39: 0 | H39: 5 | I39: 2 | J39: 0 | K39: 0 | L39: 2 | M39: 2 | N39: 2 | O39: 2 | P39: 0
C40: 멀티 | D40: 0 | E40: 0 | F40: 0 | G40: 0 | H40: 0 | I40: 0 | J40: 0 | K40: 0 | L40: 0 | M40: 0 | N40: 0 | O40: 0 | P40: 0
C41: 기타 | D41: 2 | E41: 0 | F41: 0 | G41: 0 | H41: 0 | I41: 1 | J41: 0 | K41: 0 | L41: 0 | M41: 0 | N41: 0 | O41: 0 | P41: 1
B43: CSONE부산1센터 | C43: 기술1팀 | D43: 29 | E43: 3 | F43: 3 | G43: 4 | H43: 2 | I43: 3 | J43: 0 | K43: 2 | L43: 2 | M43: 6 | N43: 1 | O43: 3 | P43: 0
C44: 기술2팀 | D44: 22 | E44: 3 | F44: 0 | G44: 5 | H44: 3 | I44: 1 | J44: 0 | K44: 2 | L44: 3 | M44: 0 | N44: 3 | O44: 2 | P44: 0
C45: 기술3팀 | D45: 43 | E45: 1 | F45: 3 | G45: 3 | H45: 6 | I45: 0 | J45: 0 | K45: 7 | L45: 7 | M45: 5 | N45: 4 | O45: 7 | P45: 0
...

Sheet 2017-12월 통계
C1: 2017년 12월 스마트원격진단 접수 현황
C3: 1. 전체 원격점검 접수 통계
C4: 구분 | F4: 12월
F5: 1 | G5: 2 | H5: 3 | I5: 4 | J5: 5 | K5: 6 | L5: 7 | M5: 8 | N5: 9 | O5: 10 | P5: 11 | Q5: 12 | R5: 13 | S5: 14 | T5: 15 | U5: 16 | V5: 17 | W5: 18 | X5: 19 | Y5: 20 | Z5: 21 | AA5: 22 | AB5: 23 | AC5: 24 | AD5: 25 | AE5: 26 | AF5: 27 | AG5: 28 | AH5: 29 | AI5: 30 | AJ5: 31
F6: 43070 | G6: 43071 | H6: 43072 | I6: 43073 | J6: 43074 | K6: 43075 | L6: 43076 | M6: 43077 | N6: 43078 | O6: 43079 | P6: 43080 | Q6: 43081 | R6: 43082 | S6: 43083 | T6: 43084 | U6: 43085 | V6: 43086 | W6: 43087 | X6: 43088 | Y6: 43089 | Z6: 43090 | AA6: 43091 | AB6: 43092 | AC6: 43093 | AD6: 43094 | AE6: 43095 | AF6: 43096 | AG6: 43097 | AH6: 43098 | AI6: 43099 | AJ6: 0
C7: 합계 | E7: =SUM(F7:AJ7) -> 1765 | F7: 81 | G7: 29 | H7: 2 | I7: 71 | J7: 51 | K7: 71 | L7: 70 | M7: 86 | N7: 21 | O7: 6 | P7: 77 | Q7: 74 | R7: 86 | S7: 87 | T7: 59 | U7: 27 | V7: 2 | W7: 92 | X7: 77 | Y7: 75 | Z7: 81 | AA7: 73 | AB7: 27 | AC7: 2 | AD7: 1 | AE7: 71 | AF7: 71 | AG7: 82 | AH7: 189 | AI7: 24 | AJ7: 0
C8: 서울1 | E8: =SUM(F8:AJ8) -> 339 | F8: 18 | G8: 4 | H8: 1 | I8: 11 | J8: 6 | K8: 14 | L8: 12 | M8: 17 | N8: 1 | O8: 0 | P8: 13 | Q8: 11 | R8: 13 | S8: 5 | T8: 10 | U8: 6 | V8: 0 | W8: 24 | X8: 14 | Y8: 19 | Z8: 18 | AA8: 11 | AB8: 5 | AC8: 0 | AD8: 0 | AE8: 15 | AF8: 18 | AG8: 23 | AH8: 47 | AI8: 3 | AJ8: 0
C9: 서울2 | E9: =SUM(F9:AJ9) -> 230 | F9: 7 | G9: 1 | H9: 0 | I9: 5 | J9: 7 | K9: 9 | L9: 7 | M9: 11 | N9: 2 | O9: 5 | P9: 15 | Q9: 12 | R9: 11 | S9: 18 | T9: 11 | U9: 2 | V9: 0 | W9: 13 | X9: 6 | Y9: 18 | Z9: 8 | AA9: 14 | AB9: 1 | AC9: 2 | AD9: 0 | AE9: 5 | AF9: 7 | AG9: 11 | AH9: 17 | AI9: 5 | AJ9: 0
C10: 부산1 | E10: =SUM(F10:AJ10) -> 375 | F10: 19 | G10: 10 | H10: 1 | I10: 15 | J10: 13 | K10: 16 | L10: 17 | M10: 16 | N10: 8 | O10: 1 | P10: 20 | Q10: 14 | R10: 25 | S10: 19 | T10: 11 | U10: 6 | V10: 2 | W10: 16 | X10: 18 | Y10: 12 | Z10: 16 | AA10: 14 | AB10: 6 | AC10: 0 | AD10: 1 | AE10: 15 | AF10: 16 | AG10: 12 | AH10: 31 | AI10: 5 | AJ10: 0
C11: 부산2 | E11: =SUM(F11:AJ11) -> 264 | F11: 17 | G11: 4 | H11: 0 | I11: 10 | J11: 10 | K11: 5 | L11: 10 | M11: 12 | N11: 2 | O11: 0 | P11: 9 | Q11: 11 | R11: 17 | S11: 8 | T11: 11 | U11: 4 | V11: 0 | W11: 14 | X11: 10 | Y11: 3 | Z11: 16 | AA11: 10 | AB11: 8 | AC11: 0 | AD11: 0 | AE11: 12 | AF11: 8 | AG11: 13 | AH11: 37 | AI11: 3 | AJ11: 0
C12: 전주 | E12: =SUM(F12:AJ12) -> 381 | F12: 12 | G12: 4 | H12: 0 | I12: 23 | J12: 12 | K12: 20 | L12: 13 | M12: 20 | N12: 4 | O12: 0 | P12: 18 | Q12: 18 | R12: 10 | S12: 25 | T12: 10 | U12: 7 | V12: 0 | W12: 18 | X12: 14 | Y12: 17 | Z12: 19 | AA12: 17 | AB12: 6 | AC12: 0 | AD12: 0 | AE12: 16 | AF12: 15 | AG12: 17 | AH12: 40 | AI12: 6 | AJ12: 0
C13: 기타(오입력) | E13: =SUM(F13:AJ13) -> 176 | F13: 8 | G13: 6 | H13: 0 | I13: 7 | J13: 3 | K13: 7 | L13: 11 | M13: 10 | N13: 4 | O13: 0 | P13: 2 | Q13: 8 | R13: 10 | S13: 12 | T13: 6 | U13: 2 | V13: 0 | W13: 7 | X13: 15 | Y13: 6 | Z13: 4 | AA13: 7 | AB13: 1 | AC13: 0 | AD13: 0 | AE13: 8 | AF13: 7 | AG13: 6 | AH13: 17 | AI13: 2 | AJ13: 0
C15: 스 캔 | E15: =SUM(F15:AJ15) -> 1905 | F15: 96 | G15: 31 | I15: 76 | J15: 53 | K15: 74 | L15: 83 | M15: 92 | N15: 26 | O15: 6 | P15: 81 | Q15: 89 | R15: 90 | S15: 88 | T15: 66 | U15: 29 | V15: 2 | W15: 95 | X15: 80 | Y15: 81 | Z15: 88 | AA15: 75 | AB15: 30 | AC15: 2 | AD15: 1 | AE15: 72 | AF15: 73 | AG15: 90 | AH15: 210 | AI15: 26
C17: 2. 센터별 접수 통계
C18: 서울1 | D18: 기술1팀 | E18: =SUM(F18:AJ18) -> 63 | F18: 5 | G18: 0 | H18: 0 | I18: 3 | J18: 1 | K18: 2 | L18: 0 | M18: 5 | N18: 0 | O18: 0 | P18: 1 | Q18: 3 | R18: 2 | S18: 1 | T18: 7 | U18: 0 | V18: 0 | W18: 6 | X18: 3 | Y18: 5 | Z18: 2 | AA18: 1 | AB18: 0 | AC18: 0 | AD18: 0 | AE18: 2 | AF18: 2 | AG18: 6 | AH18: 4 | AI18: 2 | AJ18: 0
D19: 기술2팀 | E19: =SUM(F19:AJ19) -> 69 | F19: 4 | G19: 0 | H19: 0 | I19: 3 | J19: 1 | K19: 2 | L19: 3 | M19: 3 | N19: 0 | O19: 0 | P19: 2 | Q19: 2 | R19: 3 | S19: 2 | T19: 2 | U19: 1 | V19: 0 | W19: 4 | X19: 4 | Y19: 4 | Z19: 4 | AA19: 4 | AB19: 1 | AC19: 0 | AD19: 0 | AE19: 6 | AF19: 3 | AG19: 4 | AH19: 7 | AI19: 0 | AJ19: 0
D20: 기술3팀 | E20: =SUM(F20:AJ20) -> 73 | F20: 6 | G20: 2 | H20: 0 | I20: 2 | J20: 3 | K20: 4 | L20: 0 | M20: 5 | N20: 0 | O20: 0 | P20: 4 | Q20: 3 | R20: 2 | S20: 0 | T20: 1 | U20: 1 | V20: 0 | W20: 4 | X20: 2 | Y20: 5 | Z20: 8 | AA20: 2 | AB20: 0 | AC20: 0 | AD20: 0 | AE20: 1 | AF20: 7 | AG20: 2 | AH20: 8 | AI20: 1 | AJ20: 0
D21: 기술4팀 | E21: =SUM(F21:AJ21) -> 72 | F21: 2 | G21: 1 | H21: 0 | I21: 1 | J21: 0 | K21: 1 | L21: 5 | M21: 2 | N21: 0 | O21: 0 | P21: 4 | Q21: 1 | R21: 6 | S21: 1 | T21: 0 | U21: 2 | V21: 0 | W21: 6 | X21: 5 | Y21: 5 | Z21: 3 | AA21: 1 | AB21: 3 | AC21: 0 | AD21: 0 | AE21: 6 | AF21: 2 | AG21: 3 | AH21: 12 | AI21: 0 | AJ21: 0
D22: 기술5팀 | E22: =SUM(F22:AJ22) -> 46 | F22: 1 | G22: 1 | H22: 0 | I22: 0 | J22: 1 | K22: 2 | L22: 3 | M22: 2 | N22: 1 | O22: 0 | P22: 2 | Q22: 2 | R22: 0 | S22: 0 | T22: 0 | U22: 2 | V22: 0 | W22: 2 | X22: 0 | Y22: 0 | Z22: 1 | AA22: 3 | AB22: 1 | AC22: 0 | AD22: 0 | AE22: 0 | AF22: 4 | AG22: 6 | AH22: 12 | AI22: 0 | AJ22: 0
D23: 기술6팀 | E23: =SUM(F23:AJ23) -> 0 | F23: 0 | G23: 0 | H23: 0 | I23: 0 | J23: 0 | K23: 0 | L23: 0 | M23: 0 | N23: 0 | O23: 0 | P23: 0 | Q23: 0 | R23: 0 | S23: 0 | T23: 0 | U23: 0 | V23: 0 | W23: 0 | X23: 0 | Y23: 0 | Z23: 0 | AA23: 0 | AB23: 0 | AC23: 0 | AD23: 0 | AE23: 0 | AF23: 0 | AG23: 0 | AH23: 0 | AI23: 0 | AJ23: 0
D24: 기술7팀 | E24: =SUM(F24:AJ24) -> 0 | F24: 0 | G24: 0 | H24: 0 | I24: 0 | J24: 0 | K24: 0 | L24: 0 | M24: 0 | N24: 0 | O24: 0 | P24: 0 | Q24: 0 | R24: 0 | S24: 0 | T24: 0 | U24: 0 | V24: 0 | W24: 0 | X24: 0 | Y24: 0 | Z24: 0 | AA24: 0 | AB24: 0 | AC24: 0 | AD24: 0 | AE24: 0 | AF24: 0 | AG24: 0 | AH24: 0 | AI24: 0 | AJ24: 0
D25: 기타(오입력) | E25: =SUM(F25:AJ25) -> 16 | F25: 0 | G25: 0 | H25: 1 | I25: 2 | J25: 0 | K25: 3 | L25: 1 | M25: 0 | N25: 0 | O25: 0 | P25: 0 | Q25: 0 | R25: 0 | S25: 1 | T25: 0 | U25: 0 | V25: 0 | W25: 2 | X25: 0 | Y25: 0 | Z25: 0 | AA25: 0 | AB25: 0 | AC25: 0 | AD25: 0 | AE25: 0 | AF25: 0 | AG25: 2 | AH25: 4 | AI25: 0 | AJ25: 0
C27: 서울2 | D27: 기술1팀 | E27: =SUM(F27:AJ27) -> 37 | F27: 0 | G27: 0 | H27: 0 | I27: 3 | J27: 0 | K27: 1 | L27: 1 | M27: 3 | N27: 0 | O27: 0 | P27: 7 | Q27: 2 | R27: 0 | S27: 1 | T27: 3 | U27: 0 | V27: 0 | W27: 0 | X27: 0 | Y27: 4 | Z27: 2 | AA27: 1 | AB27: 0 | AC27: 0 | AD27: 0 | AE27: 1 | AF27: 1 | AG27: 0 | AH27: 4 | AI27: 3 | AJ27: 0
D28: 기술2팀 | E28: =SUM(F28:AJ28) -> 88 | F28: 4 | G28: 1 | H28: 0 | I28: 1 | J28: 2 | K28: 2 | L28: 5 | M28: 3 | N28: 1 | O28: 3 | P28: 3 | Q28: 5 | R28: 5 | S28: 9 | T28: 6 | U28: 1 | V28: 0 | W28: 4 | X28: 4 | Y28: 5 | Z28: 3 | AA28: 8 | AB28: 0 | AC28: 0 | AD28: 0 | AE28: 2 | AF28: 1 | AG28: 4 | AH28: 5 | AI28: 1 | AJ28: 0
D29: 기술3팀 | E29: =SUM(F29:AJ29) -> 39 | F29: 0 | G29: 0 | H29: 0 | I29: 0 | J29: 1 | K29: 4 | L29: 1 | M29: 4 | N29: 0 | O29: 0 | P29: 2 | Q29: 2 | R29: 1 | S29: 1 | T29: 0 | U29: 1 | V29: 0 | W29: 2 | X29: 0 | Y29: 5 | Z29: 2 | AA29: 2 | AB29: 1 | AC29: 2 | AD29: 0 | AE29: 1 | AF29: 1 | AG29: 2 | AH29: 3 | AI29: 1 | AJ29: 0
